Workbook

Sheet Presupuesto ventas
A1: ingresos netos
A3: producto | B3: unidad | C3: 45748 | D3: 45778 | E3: 45809 | F3: 45839 | G3: 45870 | H3: 45901 | I3: 45931 | J3: 45962 | K3: 45992 | L3: 46023 | M3: 46054 | N3: 46082 | O3: total por producto
A4: CLINKER | B4: Toneladas | C4: 0 | D4: 0 | E4: 0 | F4: 0 | G4: 0 | H4: 0 | I4: 0 | J4: 0 | K4: 0 | L4: 0 | M4: 0 | N4: 0 | O4: =+SUM(C4:N4) -> 0
A5: Cemento IP25 | B5: Bolsas | C5: 351413.71 | D5: 339393.93 | E5: 354494.76 | F5: 354619.42 | G5: 345523.46 | H5: 305317.84 | I5: 350631.79 | J5: 331024.39 | K5: 360057.09 | L5: 340934.61 | M5: 349272.37 | N5: 317190.1 | O5: =+SUM(C5:N5) -> 4099873.5
B6: A granel | O6: =+SUM(C6:N6) -> 0
A7: Cemento IP30 | B7: Bolsas | C7: 9917167.4 | D7: 10623303 | E7: 10114239 | F7: 9180119.7 | G7: 11350210 | H7: 9717166.1 | I7: 9416123.8 | J7: 10121937 | K7: 10249955 | L7: 10694999 | M7: 8412943.5 | N7: 6945764.2 | O7: =+SUM(C7:N7) -> 1.1674393e+08
B8: A granel | C8: 6233365.5 | D8: 2807792.8 | E8: 1937351.6 | F8: 2872826.7 | G8: 4727104.4 | H8: 2137879.9 | I8: 3843703.1 | J8: 3350387.3 | K8: 3055433.9 | L8: 1785578.6 | M8: 1710313.9 | N8: 3143108.2 | O8: =+SUM(C8:N8) -> 37604846
A9: Cemento IP40 | B9: Bolsas | C9: 11498586 | D9: 10917741 | E9: 11735029 | F9: 11930289 | G9: 14115209 | H9: 12782124 | I9: 13468257 | J9: 14666851 | K9: 15490903 | L9: 15376967 | M9: 16134130 | N9: 11715671 | O9: =+SUM(C9:N9) -> 1.5983176e+08
B10: A granel | C10: 6282807.4 | D10: 4251963.7 | E10: 6063528 | F10: 6524106.1 | G10: 5807621.4 | H10: 7617110.6 | I10: 8130409.7 | J10: 12250267 | K10: 7081478.3 | L10: 13920110 | M10: 6369997 | N10: 12632613 | O10: =+SUM(C10:N10) -> 96932013
A11: Yeso | B11: Bolsas | C11: 689397.3 | D11: 880324.34 | E11: 1006161.7 | F11: 1013142.4 | G11: 1070280 | H11: 920451.52 | I11: 911122.72 | J11: 929140.22 | K11: 914150.9 | L11: 917600.9 | M11: 830730.1 | N11: 615386.07 | O11: =+SUM(C11:N11) -> 10697888
A12: Cemento Cola | B12: Bolsas | C12: 2881182.5 | D12: 2750900.9 | E12: 2728908.4 | F12: 3116659.5 | G12: 3177942 | H12: 3016014.6 | I12: 2901398.2 | J12: 2904481.4 | K12: 3540754.3 | L12: 2783464.4 | M12: 2562275.2 | N12: 1750975.3 | O12: =+SUM(C12:N12) -> 34114957
A13: Cemento cola 2 | C13: 363935.5 | D13: 363239.5 | E13: 362717.5 | F13: 364283.5 | G13: 364979.5 | H13: 365153.5 | I13: 362891.5 | J13: 366023.5 | K13: 368459.5 | L13: 371069.5 | M13: 371765.5 | N13: 360281.5 | O13: =+SUM(C13:N13) -> 4384800
A14: Mortero de Revoque | B14: Bolsas | C14: 28048.8 | D14: 35322.003 | E14: 40156.412 | F14: 45343.983 | G14: 42359.043 | H14: 36673.374 | I14: 36474.905 | J14: 36971.333 | K14: 36794.596 | L14: 36882.199 | M14: 33452.283 | N14: 24754.11 | O14: =+SUM(C14:N14) -> 433233.04
A15: Mortero de Mampostería | B15: Bolsas | C15: 59461.89 | D15: 59461.89 | E15: 59461.89 | F15: 59461.89 | G15: 59461.89 | H15: 59461.89 | I15: 59461.89 | J15: 59461.89 | K15: 59461.89 | L15: 59461.89 | M15: 59461.89 | N15: 59461.89 | O15: =+SUM(C15:N15) -> 713542.68
A16: Puzolana Molida | B16: Toneladas | C16: 0 | D16: 0 | E16: 0 | F16: 0 | G16: 0 | H16: 0 | I16: 0 | J16: 0 | K16: 0 | L16: 0 | M16: 0 | N16: 0 | O16: =+SUM(C16:N16) -> 0
A17: total mensual | B17: 0.87 | C17: =+SUM(C4:C16) -> 38305366 | D17: =+SUM(D4:D16) -> 33029443 | E17: =+SUM(E4:E16) -> 34402049 | F17: =+SUM(F4:F16) -> 35460852 | G17: =+SUM(G4:G16) -> 41060690 | H17: =+SUM(H4:H16) -> 36957353 | I17: =+SUM(I4:I16) -> 39480474 | J17: =+SUM(J4:J16) -> 45016544 | ... N17: =+SUM(N4:N16) -> 37565206 | O17: =+SUM(C17:N17) -> 4.6555684e+08
A18: costo de produccion de lo vendido
A19: producto | B19: unidad | C19: 45748 | D19: 45778 | E19: 45809 | F19: 45839 | G19: 45870 | H19: 45901 | I19: 45931 | J19: 45962 | K19: 45992 | L19: 46023 | M19: 46054 | N19: 46082 | O19: total por producto
A20: CLINKER | B20: Toneladas | C20: 0 | D20: 0 | E20: 0 | F20: 0 | G20: 0 | H20: 0 | I20: 0 | J20: 0 | K20: 0 | L20: 0 | M20: 0 | N20: 0 | O20: =+SUM(C20:N20) -> 0
A21: Cemento IP25 | B21: Bolsas | C21: 0 | D21: 0 | E21: 0 | F21: 0 | G21: 0 | H21: 0 | I21: 0 | J21: 0 | K21: 0 | L21: 0 | M21: 0 | N21: 0 | O21: =+SUM(C21:N21) -> 0
B22: A granel | C22: 350251.28 | D22: 350284.91 | E22: 350251.28 | F22: 350284.91 | G22: 350251.28 | H22: 350284.91 | I22: 350284.91 | J22: 350251.28 | K22: 350284.91 | L22: 350284.91 | M22: 350284.91 | N22: 350284.91 | O22: =+SUM(C22:N22) -> 4203284.4
A23: Cemento IP30 | B23: Bolsas | C23: 8636287.3 | D23: 9303755.5 | E23: 8832844 | F23: 8116655.2 | G23: 10291015 | H23: 8524291.3 | I23: 8325319.5 | J23: 8873063.4 | K23: 8974658.4 | L23: 9588897.9 | M23: 7341892.4 | N23: 6132347.8 | O23: =+SUM(C23:N23) -> 1.0294103e+08
B24: A granel | C24: 4852204.9 | D24: 2198066.8 | E24: 1512352 | F24: 2270467.4 | G24: 3831127.5 | H24: 1676405.4 | I24: 3037775.6 | J24: 2625319 | K24: 2391365.6 | L24: 1431014.4 | M24: 1334175.5 | N24: 2480522.5 | O24: =+SUM(C24:N24) -> 29640797
A25: Cemento IP40 | B25: Bolsas | C25: 10208375 | D25: 9713790.2 | E25: 10481998 | F25: 10644784 | G25: 12727556 | H25: 11487535 | I25: 12074988 | J25: 12728267 | K25: 13460538 | L25: 13633820 | M25: 14004581 | N25: 10549959 | O25: =+SUM(C25:N25) -> 1.4171619e+08
B26: A granel | C26: 4897752 | D26: 3466537.9 | E26: 4775753.4 | F26: 4981911.9 | G26: 4641535.9 | H26: 6188034.2 | I26: 6782613 | J26: 10529331 | K26: 5606895.6 | L26: 11945707 | M26: 5425933.2 | N26: 10866049 | O26: =+SUM(C26:N26) -> 80108054
A27: Yeso | B27: Bolsas | C27: 537446.51 | D27: 677079.16 | E27: 770055.68 | F27: 869534.1 | G27: 825511.55 | H27: 706943.1 | I27: 704249.65 | J27: 716142.45 | K27: 705588.37 | L27: 709256.93 | M27: 638935.01 | N27: 474313.86 | O27: =+SUM(C27:N27) -> 8335056.4
A28: Cemento Cola | B28: Bolsas | C28: 1677738 | D28: 1604502.5 | E28: 1593636.3 | F28: 1813372.9 | G28: 1846007.2 | H28: 1751231.1 | I28: 1693671.8 | J28: 1683033.3 | K28: 2040087.9 | L28: 1594067.6 | M28: 1465033.9 | N28: 1028454.1 | O28: =+SUM(C28:N28) -> 19790836
A29: Cemento cola 2 | O29: =+SUM(C29:N29) -> 0
A30: Mortero de Revoque | B30: Bolsas | C30: 22936.232 | D30: 28895.277 | E30: 32863.231 | F30: 37108.64 | G30: 35229.953 | H30: 30169.789 | I30: 30054.895 | J30: 30562.494 | K30: 30111.986 | L30: 30268.499 | M30: 27267.545 | N30: 20242.079 | O30: =+SUM(C30:N30) -> 355710.62
A31: Mortero de Mampostería | B31: Bolsas | O31: =+SUM(C31:N31) -> 0
A32: Puzolana Molida | B32: Toneladas | C32: 0 | D32: 0 | E32: 0 | F32: 0 | G32: 0 | H32: 0 | I32: 0 | J32: 0 | K32: 0 | L32: 0 | M32: 0 | N32: 0 | O32: =+SUM(C32:N32) -> 0
A33: total mensual | B33: Bs | C33: =+SUM(C20:C32) -> 31182991 | D33: =+SUM(D20:D32) -> 27342912 | E33: =+SUM(E20:E32) -> 28349754 | F33: =+SUM(F20:F32) -> 29084119 | G33: =+SUM(G20:G32) -> 34548234 | H33: =+SUM(H20:H32) -> 30714895 | I33: =+SUM(I20:I32) -> 32998958 | J33: =+SUM(J20:J32) -> 37535970 | ... N33: =+SUM(N20:N32) -> 31902173 | O33: =+SUM(C33:N33) -> 3.8709096e+08
A36: producto | B36: unidad | C36: IT | D36: CV | E36: margen bruto | F36: MC (%)
A37: CLINKER | B37: Toneladas | C37: =+O4 -> 0 | D37: =+O20 -> 0 | E37: =+C37-D37 -> 0
A38: Cemento IP25 | B38: Bolsas | C38: =+O5 -> 4099873.5 | D38: =+O22 -> 4203284.4 | E38: =+C38-D38 -> -103410.92 | F38: =+E38/C38 -> -0.025222954
B39: A granel | C39: =+O6 -> 0 | E39: =+C39-D39 -> 0
A40: Cemento IP30 | B40: Bolsas | C40: =+O7 -> 1.1674393e+08 | D40: =+O23 -> 1.0294103e+08 | E40: =+C40-D40 -> 13802900 | F40: =+E40/C40 -> 0.11823227
B41: A granel | C41: =+O8 -> 37604846 | D41: =+O24 -> 29640797 | E41: =+C41-D41 -> 7964049.3 | F41: =+E41/C41 -> 0.21178253
A42: Cemento IP40 | B42: Bolsas | C42: =+O9 -> 1.5983176e+08 | D42: =+O25 -> 1.4171619e+08 | E42: =+C42-D42 -> 18115563 | F42: =+E42/C42 -> 0.11334145
B43: A granel | C43: =+O10 -> 96932013 | D43: =+O26 -> 80108054 | E43: =+C43-D43 -> 16823959 | F43: =+E43/C43 -> 0.17356452
...

Sheet Presupuesto 25
A1: P R E S U P U E S T O D E L E S T A D O D E R E S U L T A D O S
A3: C O D I G O | B3: D E T A L L E D E C U E N T A | C3: 45397 | D3: 45427 | E3: 45457 | F3: 45487 | G3: 45517 | H3: 45547 | I3: 45577 | J3: 45607 | K3: 45637 | L3: 45667 | M3: 45697 | N3: 45727 | O3: TOTAL
C4: Bs | D4: Bs | E4: Bs | F4: Bs | G4: Bs | H4: Bs | I4: Bs | J4: Bs | K4: Bs | L4: Bs | M4: Bs | N4: Bs | O4: Bs
A6: 3 0 00 00 | B6: I N G R E S O S | C6: =+C8 -> 39913012 | D6: =+D8 -> 34637088 | E6: =+E8 -> 36009694 | F6: =+F8 -> 37068498 | G6: =+G8 -> 42668336 | H6: =+H8 -> 38564999 | I6: =+I8 -> 41088120 | J6: =+J8 -> 46624190 | ... N6: =+N8 -> 39172852 | O6: =SUM(C6:N6) -> 4.8484858e+08
A8: 3 1 00 00 | B8: INGRESOS NETOS | C8: =+C9+C17 -> 39913012 | D8: =+D9+D17 -> 34637088 | E8: =+E9+E17 -> 36009694 | F8: =+F9+F17 -> 37068498 | G8: =+G9+G17 -> 42668336 | H8: =+H9+H17 -> 38564999 | I8: =+I9+I17 -> 41088120 | J8: =+J9+J17 -> 46624190 | ... N8: =+N9+N17 -> 39172852 | O8: =SUM(C8:N8) -> 4.8484858e+08
A9: 3 1 01 00 | B9: INGRESOS OPERATIVOS | C9: =SUM(C10:C10)+C16 -> 39913012 | D9: =SUM(D10:D10)+D16 -> 34637088 | E9: =SUM(E10:E10)+E16 -> 36009694 | F9: =SUM(F10:F10)+F16 -> 37068498 | G9: =SUM(G10:G10)+G16 -> 42668336 | H9: =SUM(H10:H10)+H16 -> 38564999 | I9: =SUM(I10:I10)+I16 -> 41088120 | J9: =SUM(J10:J10)+J16 -> 46624190 | ... N9: =SUM(N10:N10)+N16 -> 39172852 | O9: =SUM(C9:N9) -> 4.8484858e+08
A10: 3 1 01 01 | B10: INGRESOS POR VTA. DE PRODUCTOS | C10: =SUM(C11:C15) -> 38305366 | D10: =SUM(D11:D15) -> 33029443 | E10: =SUM(E11:E15) -> 34402049 | F10: =SUM(F11:F15) -> 35460852 | G10: =SUM(G11:G15) -> 41060690 | H10: =SUM(H11:H15) -> 36957353 | I10: =SUM(I11:I15) -> 39480474 | J10: =SUM(J11:J15) -> 45016544 | ... N10: =SUM(N11:N15) -> 37565206 | O10: =SUM(C10:N10) -> 4.6555684e+08
B11: CEMENTO | C11: 34283340 | D11: 28940194 | E11: 30204643 | F11: 30861961 | G11: 36345667 | H11: 32559598 | I11: 35209125 | J11: 40720466 | K11: 36237827 | L11: 42118590 | M11: 32976657 | N11: 34754347 | O11: =SUM(C11:N11) -> 4.1521242e+08
B12: YESO | C12: 689397.3 | D12: 880324.34 | E12: 1006161.7 | F12: 1013142.4 | G12: 1070280 | H12: 920451.52 | I12: 911122.72 | J12: 929140.22 | K12: 914150.9 | L12: 917600.9 | M12: 830730.1 | N12: 615386.07 | O12: =SUM(C12:N12) -> 10697888
B13: MORTEROS SECOS | C13: 3332628.7 | D13: 3208924.3 | E13: 3191244.2 | F13: 3585748.8 | G13: 3644742.4 | H13: 3477303.4 | I13: 3360226.5 | J13: 3366938.1 | K13: 4005470.3 | L13: 3250878 | M13: 3026954.8 | N13: 2195472.8 | O13: =SUM(C13:N13) -> 39646532
B14: PUZOLANA MOLIDA | C14: 0 | D14: 0 | E14: 0 | F14: 0 | G14: 0 | H14: 0 | I14: 0 | J14: 0 | K14: 0 | L14: 0 | M14: 0 | N14: 0 | O14: =SUM(C14:N14) -> 0
B15: CLINKER | C15: 0 | D15: 0 | E15: 0 | F15: 0 | G15: 0 | H15: 0 | I15: 0 | J15: 0 | K15: 0 | L15: 0 | M15: 0 | N15: 0 | O15: =SUM(C15:N15) -> 0
B16: SERVICIO FLETES Y ESTIBAJES | C16: 1607645.6 | D16: 1607645.6 | E16: 1607645.6 | F16: 1607645.6 | G16: 1607645.6 | H16: 1607645.6 | I16: 1607645.6 | J16: 1607645.6 | K16: 1607645.6 | L16: 1607645.6 | M16: 1607645.6 | N16: 1607645.6 | O16: =SUM(C16:N16) -> 19291748
A17: 3 1 02 00 | B17: INGRESOS NO OPERATIVOS | C17: =SUM(C18:C22) -> 0 | D17: =SUM(D18:D22) -> 0 | E17: =SUM(E18:E22) -> 0 | F17: =SUM(F18:F22) -> 0 | G17: =SUM(G18:G22) -> 0 | H17: =SUM(H18:H22) -> 0 | I17: =SUM(I18:I22) -> 0 | J17: =SUM(J18:J22) -> 0 | ... N17: =SUM(N18:N22) -> 0 | O17: =SUM(C17:N17) -> 0
A18: 3 1 02 01 | B18: PULPERIAS Y MAT. ALMACEN | O18: =SUM(C18:N18) -> 0
A19: 3 1 02 02 | B19: VENTA DE ACTIVOS
A20: 3 1 02 03 | B20: INGRESOS FINANCIEROS | O20: =SUM(C20:N20) -> 0
A21: 3 1 02 04 | B21: OTROS INGRESOS Y RESIDUOS | O21: =SUM(C21:N21) -> 0
O22: =SUM(C22:N22) -> 0
A23: 3 1 03 00 | B23: DESCUENTOS, DEVOLUCIONES, REBAJAS | C23: =SUM(C24) -> 0 | D23: =SUM(D24) -> 0 | E23: =SUM(E24) -> 0 | F23: =SUM(F24) -> 0 | G23: =SUM(G24) -> 0 | H23: =SUM(H24) -> 0 | I23: =SUM(I24) -> 0 | J23: =SUM(J24) -> 0 | ... N23: =SUM(N24) -> 0 | O23: =SUM(C23:N23) -> 0
A24: 3 1 03 01 | B24: DESCUENTOS, DEVOLUCIONES, REBAJAS | D24: 0 | E24: 0 | F24: 0 | G24: 0 | H24: 0 | I24: 0 | J24: 0 | K24: 0 | L24: 0 | M24: 0 | N24: 0 | O24: =SUM(C24:N24) -> 0
O25: =SUM(C25:N25) -> 0
A26: 4 0 00 00 | B26: G A S T O S | C26: =C27+C40+C55+C70+C74+C78+C82 -> 38385752 | D26: =D27+D40+D55+D70+D74+D78+D82 -> 34363744 | E26: =E27+E40+E55+E70+E74+E78+E82 -> 35417917 | F26: =F27+F40+F55+F70+F74+F78+F82 -> 36188793 | G26: =G27+G40+G55+G70+G74+G78+G82 -> 41846006 | H26: =H27+H40+H55+H70+H74+H78+H82 -> 37871173 | I26: =I27+I40+I55+I70+I74+I78+I82 -> 40242239 | J26: =J27+J40+J55+J70+J74+J78+J82 -> 44970151 | ... N26: =N27+N40+N55+N70+N74+N78+N82 -> 39079411 | O26: =SUM(C26:N26) -> 4.7372727e+08
A27: 4 1 00 00 | B27: COSTO DE PRODUCCION DE LO VENDIDO | C27: =+C28+C35 -> 31191325 | D27: =+D28+D35 -> 27351246 | E27: =+E28+E35 -> 28358087 | F27: =+F28+F35 -> 29092452 | G27: =+G28+G35 -> 34556567 | H27: =+H28+H35 -> 30723229 | I27: =+I28+I35 -> 33007291 | J27: =+J28+J35 -> 37544304 | ... N27: =+N28+N35 -> 31910506 | O27: =SUM(C27:N27) -> 3.8719096e+08
A28: 4 1 01 00 | B28: COSTO DE PRODUCCION DE LO VENDIDO | C28: =SUM(C29) -> 31182991 | D28: =SUM(D29) -> 27342912 | E28: =SUM(E29) -> 28349754 | F28: =SUM(F29) -> 29084119 | G28: =SUM(G29) -> 34548234 | H28: =SUM(H29) -> 30714895 | I28: =SUM(I29) -> 32998958 | J28: =SUM(J29) -> 37535970 | ... N28: =SUM(N29) -> 31902173 | O28: =SUM(C28:N28) -> 3.8709096e+08
A29: 4 1 01 01 | B29: COSTO DE PRODUCCION DE LO VENDIDO | C29: =SUM(C30:C34) -> 31182991 | D29: =SUM(D30:D34) -> 27342912 | E29: =SUM(E30:E34) -> 28349754 | F29: =SUM(F30:F34) -> 29084119 | G29: =SUM(G30:G34) -> 34548234 | H29: =SUM(H30:H34) -> 30714895 | I29: =SUM(I30:I34) -> 32998958 | J29: =SUM(J30:J34) -> 37535970 | ... N29: =SUM(N30:N34) -> 31902173 | O29: =SUM(C29:N29) -> 3.8709096e+08
B30: CEMENTO | C30: 28944871 | D30: 25032435 | E30: 25953199 | F30: 26364103 | G30: 31841485 | H30: 28226551 | I30: 30570981 | J30: 35106232 | K30: 30783742 | L30: 36949725 | M30: 28456867 | N30: 30379163 | O30: =SUM(C30:N30) -> 3.5860936e+08
B31: YESO | C31: 537446.51 | D31: 677079.16 | E31: 770055.68 | F31: 869534.1 | G31: 825511.55 | H31: 706943.1 | I31: 704249.65 | J31: 716142.45 | K31: 705588.37 | L31: 709256.93 | M31: 638935.01 | N31: 474313.86 | O31: =SUM(C31:N31) -> 8335056.4
B32: MORTEROS SECOS | C32: 1700674.2 | D32: 1633397.8 | E32: 1626499.5 | F32: 1850481.5 | G32: 1881237.2 | H32: 1781400.9 | I32: 1723726.7 | J32: 1713595.8 | K32: 2070199.9 | L32: 1624336.1 | M32: 1492301.4 | N32: 1048696.1 | O32: =SUM(C32:N32) -> 20146547
B33: PUZOLANA MOLIDA | C33: 0 | D33: 0 | E33: 0 | F33: 0 | G33: 0 | H33: 0 | I33: 0 | J33: 0 | K33: 0 | L33: 0 | M33: 0 | N33: 0 | O33: =SUM(C33:N33) -> 0
B34: CLINKER | C34: 0 | D34: 0 | E34: 0 | F34: 0 | G34: 0 | H34: 0 | I34: 0 | J34: 0 | K34: 0 | L34: 0 | M34: 0 | N34: 0 | O34: =SUM(C34:N34) -> 0
A35: 4 1 0 2 00 | B35: EGRESOS NO OPERATIVOS | C35: =+C36 -> 8333.33 | D35: =+D36 -> 8333.33 | E35: =+E36 -> 8333.33 | F35: =+F36 -> 8333.33 | G35: =+G36 -> 8333.33 | H35: =+H36 -> 8333.33 | I35: =+I36 -> 8333.33 | J35: =+J36 -> 8333.33 | ... N35: =+N36 -> 8333.37 | O35: =SUM(C35:N35) -> 100000
A36: 4 1 0 2 01 | B36: EGRESOS NO OPERATIVOS | C36: =+C37+C38 -> 8333.33 | D36: =+D37+D38 -> 8333.33 | E36: =+E37+E38 -> 8333.33 | F36: =+F37+F38 -> 8333.33 | G36: =+G37+G38 -> 8333.33 | H36: =+H37+H38 -> 8333.33 | I36: =+I37+I38 -> 8333.33 | J36: =+J37+J38 -> 8333.33 | ... N36: =+N37+N38 -> 8333.37 | O36: =SUM(C36:N36) -> 100000
B37: FABRICACION Y MONTAJE | C37: 0 | D37: 0 | E37: 0 | F37: 0 | G37: 0 | H37: 0 | I37: 0 | J37: 0 | K37: 0 | L37: 0 | M37: 0 | N37: 0 | O37: =SUM(C37:N37) -> 0
B38: PLANTA AGREGADOS | C38: 8333.33 | D38: 8333.33 | E38: 8333.33 | F38: 8333.33 | G38: 8333.33 | H38: 8333.33 | I38: 8333.33 | J38: 8333.33 | K38: 8333.33 | L38: 8333.33 | M38: 8333.33 | N38: 8333.37 | O38: =SUM(C38:N38) -> 100000
B39: REP.MANTTO. ACTIVOS | C39: 989.53144 | D39: 989.53144 | E39: 989.53144 | F39: 989.53144 | G39: 989.53144 | H39: 989.53144 | I39: 989.53144 | J39: 989.53144 | K39: 989.53144 | L39: 989.53144 | M39: 989.53144 | N39: 989.53144 | O39: =SUM(C39:N39) -> 11874.377
A40: 4 2 00 00 | B40: GASTOS DE ADMINISTRACION | C40: =C41+C45+C48+C52 -> 978326.19 | D40: =D41+D45+D48+D52 -> 978326.19 | E40: =E41+E45+E48+E52 -> 978326.19 | F40: =F41+F45+F48+F52 -> 978326.19 | G40: =G41+G45+G48+G52 -> 978326.19 | H40: =H41+H45+H48+H52 -> 978326.19 | I40: =I41+I45+I48+I52 -> 978326.19 | J40: =J41+J45+J48+J52 -> 978326.19 | ... N40: =N41+N45+N48+N52 -> 978326.19 | O40: =SUM(C40:N40) -> 11739914
A41: 4 2 01 00 | B41: OBRA DE MANO | C41: =SUM(C42:C44) -> 556964.24 | D41: =SUM(D42:D44) -> 556964.24 | E41: =SUM(E42:E44) -> 556964.24 | F41: =SUM(F42:F44) -> 556964.24 | G41: =SUM(G42:G44) -> 556964.24 | H41: =SUM(H42:H44) -> 556964.24 | I41: =SUM(I42:I44) -> 556964.24 | J41: =SUM(J42:J44) -> 556964.24 | ... N41: =SUM(N42:N44) -> 556964.24 | O41: =SUM(C41:N41) -> 6683570.9
A42: 4 2 01 01 | B42: SUELDOS Y SALARIOS | C42: 401362.2 | D42: 401362.2 | E42: 401362.2 | F42: 401362.2 | G42: 401362.2 | H42: 401362.2 | I42: 401362.2 | J42: 401362.2 | K42: 401362.2 | L42: 401362.2 | M42: 401362.2 | N42: 401362.2 | O42: =SUM(C42:N42) -> 4816346.4
A43: 4 2 01 02 | B43: APORTES PATRONALES | C43: 67734.639 | D43: 67734.639 | E43: 67734.639 | F43: 67734.639 | G43: 67734.639 | H43: 67734.639 | I43: 67734.639 | J43: 67734.639 | K43: 67734.639 | L43: 67734.639 | M43: 67734.639 | N43: 67734.639 | O43: =SUM(C43:N43) -> 812815.67
...

Sheet BCO
A1: BANCO PyME DE LA COMUNIDAD S.A.
A2: COMPOSICIÓN ACCIONARIA AL 31 de agosto de 2025
A4: Nº | B4: NOMBRE O RAZON SOCIAL DEL ACCIONISTA | C4: Composición Accionaria al 31.08.2025
C5: Paquete accionario - Bs | D5: Cantidad de acciones (*) | E5: Participación accionaria | F5: Paquete accionario - USD.
A6: 1 | B6: Cooperativa Multiactiva COBOCE R.L | C6: 33002900 | D6: 3300290 | E6: 0.54158866 | F6: 4810918.4
A7: 2 | B7: OIKOCREDIT, Ecumenical Development Cooperative Society U.A. | C7: 10250610 | D7: 1025061 | E7: 0.16821606 | F7: 1494258
A8: 3 | B8: Otros accionistas | C8: 17683690 | D8: 1768369 | E8: 0.29019532 | F8: 2577797.4
A9: TOTALES | C9: 60937200 | D9: 6093720 | E9: 1 | F9: 8882973.8
A10: (*) | B10: A valor nominal de Bs10 por acción
B12: DETERMINACIÓN DEL VALOR PATRIMONIAL PROPORCIONAL (VPP)
B14: DETALLE | C14: Valores
B15: Patrimonio (P) al 31.08.2025 en Bs | C15: 48226221 | H15: VPP: Valor Patrimonial Proporcional
B16: Capital Social Preferente (CSP) en Bs | C16: 0 | H16: P: Patrimonio
B17: Aportes Pendientes de Capitalización (APC) en Bs | C17: 53625.59 | D17: VPP = | E17: P - CSP - APC - DAAP | H17: CSP: Capital Social Preferente
B18: Dividendos Acumulativos de las Acciones Preferentes (DAAP) en Bs | C18: 0 | E18: NAOC | H18: APC: Aportes Pendientes de Capitalización
B19: Número de Acciones Ordinarias en Circulación (NAOC) | C19: 6093720 | H19: DAAP: Dividendos Acumulativos de las Acciones Preferentes
B20: Valor patrimonial proporcional - VPP en Bs | C20: 7.9052853 | H20: NAOC: Número de Acciones Ordinarias en Circulación
B21: Valor nominal de las acciones - Bs | C21: 10
A23: COMPOSICIÓN ACCIONARIA AL VPP AL 31 de agosto de 2025
A25: Nº | B25: NOMBRE O RAZON SOCIAL DEL ACCIONISTA | C25: Composición Accionaria al 31.08.2025 | F25: Composición accionaria al VPP al 31.08.2025
C26: Paquete accionario - Bs | D26: Cantidad de acciones (*) | E26: Participación accionaria | F26: Patirmonio contable - Bs | G26: VPP - Bs | H26: Paquete accionario al VPP - Bs | I26: Paquete accionario al VPP - USD.
A27: 1 | B27: Cooperativa Multiactiva COBOCE R.L | C27: 33002900 | D27: 3300290 | E27: 0.54158872 | F27: 48226221 | G27: 7.9052853 | H27: 26089734 | I27: 3803168.2
A28: 2 | B28: OIKOCREDIT, Ecumenical Development Cooperative Society U.A. | C28: 10250610 | D28: 1025061 | E28: 0.16821597 | F28: 48226221 | G28: 7.9052853 | H28: 8103399.7 | I28: 1181253.6
A29: 3 | B29: Otros accionistas | C29: 17683690 | D29: 1768369 | E29: 0.29019532 | F29: 48226221 | G29: 7.9052853 | H29: 13979461 | I29: 2037822.4
A30: TOTALES | C30: 60937200 | D30: 6093720 | E30: 1 | H30: 48172595 | I30: 7022244.2
A31: (*) | B31: A valor nominal de Bs10 por acción
B33: PAQUETE ACCIONARIO DE COBOCE AL VPP AL 31.08.2025
B35: DETALLE | C35: Bs | D35: USD. | G35: OTRAS CUENTAS PATRIMONIALES
B36: Aporte inicial en efectivo | C36: 11725000 | D36: 2263513.5 | H36: APORTES NO CAPITALIZADOS | I36: 53625.59
B37: Aportes adicionales en efectivo | C37: 43571970 | D37: 4088241.6 | H37: RESERVAS | I37: 4507876.4
B38: Reducción Voluntaria de Capital Pagado | C38: -43409586 | D38: -6327927.9 | H38: RESULTADOS ACUMULADOS | I38: -17272481
B39: Total aportes realizados en efectivo | C39: 11887384 | D39: 23827.173 | H39: TOTAL OTRAS CUENTAS PATRIMONIALES | I39: -12710979
B40: Capitalización de utilidades | C40: 21115510 | D40: 3078062.7 | H40: CAPITAL PAGADO | I40: 60937200
B41: Paquete accionario (Capital Social) | C41: 33002894 | D41: 4810917.6 | H41: TOTAL PATRIMONIO | I41: 48226221
B42: Distribución de otras cuentas patrimoniales | C42: -6913165.9 | D42: -1007750.1
B43: Paquete accionario al VVP | C43: 26089728 | D43: 3803167.4
B44: Número de acciones de COBOCE | C44: 3300290
B45: Valor Patrimonial Proporcional de las acciones de COBOCE | C45: 7.9052836

Sheet Ventas
A1: Gestion | B1: Ventas | C1: tasa de crecimiento en ventas
A2: =+'EEFF proyectados'!N1 -> 2020 | B2: =+'EEFF proyectados'!N5 -> 3.7943563e+08
A3: =+A2+1 -> 2021 | B3: =+'EEFF proyectados'!AA5 -> 3.5215099e+08 | C3: =+B3/B2-1 -> -0.071908492
A4: =+A3+1 -> 2022 | B4: =+'EEFF proyectados'!AN5 -> 4.1815596e+08 | C4: =+B4/B3-1 -> 0.18743373
A5: =+A4+1 -> 2023 | B5: =+'EEFF proyectados'!BA5 -> 4.3776462e+08 | C5: =+B5/B4-1 -> 0.046893168
A6: =+A5+1 -> 2024 | B6: =+'EEFF proyectados'!BN5 -> 4.3212218e+08 | C6: =+B6/B5-1 -> -0.012889213 | H6: Monto | I6: 200000
A7: =+A6+1 -> 2025 | B7: =+B6*(1+C7) -> 6.6581192e+08 | C7: =+('Control y Supuestos'!F56/MONTH('Control y Supuestos'!F52)*12*0.7)/'Control y Supuestos'!E56 -> 0.54079554 | H7: Precio de compra | I7: 49
A8: =+A7+1 -> 2026 | B8: =+B7*(1+C8) -> 6.6581192e+08 | C8: 0 | H8: Cantidad | I8: =+ROUND(I6/I7,0) -> 4082
A9: =+A8+1 -> 2027 | B9: =+B8*(1+C9) -> 6.6581192e+08 | C9: 0 | H9: Precio de venta | I9: 53
A10: =+A9+1 -> 2028 | B10: =+B9*(1+C10) -> 6.6581192e+08 | C10: 0 | H10: margen unitario | I10: =+I9-I7 -> 4
A11: =+A10+1 -> 2029 | B11: =+B10*(1+C11) -> 6.6581192e+08 | C11: 0 | H11: margen de utilidad | I11: =+I10*I8 -> 16328
A12: =+A11+1 -> 2030 | B12: =+B11*(1+C12) -> 6.6581192e+08 | C12: 0

Sheet Obligaciones financieras
N1: Nro de la operación | Q1: 3167401 | S1: Plan Banco | AE1: Nro de la operación | AG1: 2767412 | AT1: Nro de la operación | AV1: 2764418 | BI1: Nro de la operación | BK1: 1271559 | BX1: Nro de la operación | BZ1: 1358960 | CN1: Nro de la operación | CP1: 1295150 | CW1: Nro de la operación | CY1: 101194346 | DF1: Nro de la operación | DH1: 315101121500077 | DO1: Nro de la operación | DQ1: 315101121500078f | EG1: Nro de la operación | EI1: 315101121500021 | EQ1: Nro de la operación | ES1: 2010014418 | EZ1: Nro de la operación | FB1: 2010014118 | FI1: Nro de la operación | FK1: 2010013918 | FR1: Nro de la operación | FT1: 2010014218 | GA1: Nro de la operación | GC1: 2010014318 | GJ1: Nro de la operación | GL1: 2010014018
N2: Entidad | Q2: Fideicomiso - Banco Unión | S2: 1. | T2: Visitar el lunes al banco, habilitando al doctor Murillo como representante | AE2: Entidad | AG2: Banco Unión | AT2: Entidad | AV2: Banco Unión | BI2: Entidad | BK2: Banco Bisa | BX2: Entidad | BZ2: Banco Bisa | CN2: Entidad | CP2: Banco Bisa | CW2: Entidad | CY2: Banco Ganadero | DF2: Entidad | DH2: Banco de Desarrollo Productivo | DO2: Entidad | DQ2: Banco de Desarrollo Productivo | EG2: Entidad | EI2: Banco de Desarrollo Productivo | EQ2: Entidad | ES2: BNB leasing | EZ2: Entidad | FB2: BNB leasing | FI2: Entidad | FK2: BNB leasing | FR2: Entidad | FT2: BNB leasing | GA2: Entidad | GC2: BNB leasing | GJ2: Entidad | GL2: BNB leasing
N3: Cod. Entidad | Q3: FID - BUN | S3: 2 | T3: tenemos un periodo de 30 dias para comenzar la demanda (coboce no presenta demanda Banco no presenta ejecucion) | AE3: Cod. Entidad | AG3: BUN | AT3: Cod. Entidad | AV3: BUN | BI3: Cod. Entidad | BK3: BIS | BX3: Cod. Entidad | BZ3: BIS | CN3: Cod. Entidad | CP3: BIS | CW3: Cod. Entidad | CY3: GAN | DF3: Cod. Entidad | DH3: BDP | DO3: Cod. Entidad | DQ3: BDP | EG3: Cod. Entidad | EI3: BDP | EQ3: Cod. Entidad | ES3: BNL | EZ3: Cod. Entidad | FB3: BNL | FI3: Cod. Entidad | FK3: BNL | FR3: Cod. Entidad | FT3: BNL | GA3: Cod. Entidad | GC3: BNL | GJ3: Cod. Entidad | GL3: BNL
N4: Moneda | Q4: Bolivanos | S4: 3 | T4: Dacion en pago (BANCO y PILAT) | AE4: Moneda | AG4: Bolivanos | AT4: Moneda | AV4: Bolivanos | BI4: Moneda | BK4: Bolivanos | BX4: Moneda | BZ4: Bolivanos | CN4: Moneda | CP4: Bolivanos | CW4: Moneda | CY4: Bolivanos | DF4: Moneda | DH4: Bolivanos | DO4: Moneda | DQ4: Bolivanos | EG4: Moneda | EI4: Bolivanos | EQ4: Moneda | ES4: Bolivanos | EZ4: Moneda | FB4: Bolivanos | FI4: Moneda | FK4: Bolivanos | FR4: Moneda | FT4: Bolivanos | GA4: Moneda | GC4: Bolivanos | GJ4: Moneda | GL4: Bolivanos
N5: Tasa | Q5: 0.06 | S5: 4 | T5: Alternativamente hacemos seguimiento a la demanda del bnaco antes que dicte la sentencia preliminar del banco para parar | AE5: Tasa | AG5: 0.055 | AT5: Tasa | AV5: 0.06 | BI5: Tasa | BK5: 0.06 | BX5: Tasa | BZ5: 0.06 | CN5: Tasa | CP5: 0.06 | CW5: Tasa | CY5: 0.06 | DF5: Tasa | DH5: 0.058 | DO5: Tasa | DQ5: 0.0582 | EG5: Tasa | EI5: 0.0599 | EQ5: Tasa | ES5: 0.06 | EZ5: Tasa | FB5: 0.06 | FI5: Tasa | FK5: 0.06 | FR5: Tasa | FT5: 0.06 | GA5: Tasa | GC5: 0.06 | GJ5: Tasa | GL5: 0.06
N6: Periodicidad | Q6: Trimestral | S6: 5 | AE6: Periodicidad | AG6: Trimestral | AT6: Periodicidad | AV6: Trimestral | BI6: Periodicidad | BK6: Trimestral | BX6: Periodicidad | BZ6: Trimestral | CN6: Periodicidad | CP6: Trimestral | CW6: Periodicidad | CY6: Mensual | DF6: Periodicidad | DH6: Trimestral | DO6: Periodicidad | DQ6: Trimestral | EG6: Periodicidad | EI6: Trimestral | EQ6: Periodicidad | ES6: Trimestral | EZ6: Periodicidad | FB6: Trimestral | FI6: Periodicidad | FK6: Trimestral | FR6: Periodicidad | FT6: Trimestral | GA6: Periodicidad | GC6: Trimestral | GJ6: Periodicidad | GL6: Trimestral
N7: inicio
N8: vencimiento | Q8: =+MAX(O25:O822) -> 48248 | AE8: vencimiento | AG8: =+MAX(AE25:AE822) -> 48058 | AT8: vencimiento | AV8: =+MAX(AT25:AT822) -> 48997 | BI8: vencimiento | BK8: =+MAX(BI25:BI822) -> 47107 | BX8: vencimiento | BZ8: =+MAX(BX25:BX822) -> 47398 | CN8: vencimiento | CP8: =+MAX(CN25:CN822) -> 47375 | CW8: vencimiento | CY8: =+MAX(CW25:CW822) -> 46609 | DF8: vencimiento | DH8: =+MAX(DF25:DF822) -> 49111 | DO8: vencimiento | DQ8: =+MAX(DO25:DO822) -> 48765 | EG8: vencimiento | EI8: =+MAX(EG25:EG822) -> 49111 | EQ8: vencimiento | ES8: =+MAX(EQ25:EQ822) -> 46552 | EZ8: vencimiento | FB8: =+MAX(EZ25:EZ822) -> 46552 | FI8: vencimiento | FK8: =+MAX(FI25:FI822) -> 46552 | FR8: vencimiento | FT8: =+MAX(FR25:FR822) -> 46552 | GA8: vencimiento | GC8: =+MAX(GA25:GA822) -> 46714 | GJ8: vencimiento | GL8: =+MAX(GJ25:GJ822) -> 46714
N9: plazo | Q9: =+Q8-[2]Caracteristicas!$I$19 -> 2348 | AG9: =+AG8-[2]Caracteristicas!$I$19 -> 2158 | AV9: =+AV8-[2]Caracteristicas!$I$19 -> 3097 | BK9: =+BK8-[2]Caracteristicas!$I$19 -> 1207 | BZ9: =+BZ8-[2]Caracteristicas!$I$19 -> 1498 | CP9: =+CP8-[2]Caracteristicas!$I$19 -> 1475 | CY9: =+CY8-[2]Caracteristicas!$I$19 -> 709 | DH9: =+DH8-[2]Caracteristicas!$I$19 -> 3211 | DQ9: =+DQ8-[2]Caracteristicas!$I$19 -> 2865 | EI9: =+EI8-[2]Caracteristicas!$I$19 -> 3211 | ES9: =+ES8-[2]Caracteristicas!$I$19 -> 652 | FB9: =+FB8-[2]Caracteristicas!$I$19 -> 652 | FK9: =+FK8-[2]Caracteristicas!$I$19 -> 652 | FT9: =+FT8-[2]Caracteristicas!$I$19 -> 652 | GC9: =+GC8-[2]Caracteristicas!$I$19 -> 814 | GL9: =+GL8-[2]Caracteristicas!$I$19 -> 814
N10: Saldo a capital inicial
N11: Saldo Adeudado | Q11: =+Q13/Q12 -> 2.3034329e+08 | AG11: =+AG13/AG12 -> 1241907.9 | AV11: =+AV13/AV12 -> 51796168 | BK11: =+BK13/BK12 -> 53476614 | BZ11: =+BZ13/BZ12 -> 4838608.1 | CP11: =+CP13/CP12 -> 1669085.9 | CY11: =+CY13/CY12 -> 29810000 | DH11: =+DH13/DH12 -> 9174681.5 | DQ11: =+DQ13/DQ12 -> 8467855 | EI11: =+EI13/EI12 -> 2794681.5 | ES11: =+ES13/ES12 -> 309433.84 | FB11: =+FB13/FB12 -> 309433.84 | FK11: =+FK13/FK12 -> 309433.84 | FT11: =+FT13/FT12 -> 309433.84 | GC11: =+GC13/GC12 -> 388403.55 | GL11: =+GL13/GL12 -> 388403.55
N12: % correspondiente a CEMENTO | Q12: 0.57390185 | AE12: % correspondiente a CEMENTO | AG12: 1 | AT12: % correspondiente a CEMENTO | AV12: =+AV13/AV15 -> 0.3088359 | BI12: % correspondiente a CEMENTO | BK12: 1 | BX12: % correspondiente a CEMENTO | BZ12: =+CA27/254312.71 -> 0.22702943 | CN12: % correspondiente a CEMENTO | CP12: 1 | CW12: % correspondiente a CEMENTO | CY12: =++CY13/CY15 -> 0.86082018 | DF12: % correspondiente a CEMENTO | DH12: 0.99370812 | DO12: % correspondiente a CEMENTO | DQ12: =+DQ13/DQ15 -> 0.13104947 | DR12: Antes | DT12: 0.38897016 | EG12: % correspondiente a CEMENTO | EI12: 1 | EQ12: % correspondiente a CEMENTO | ES12: 1 | EZ12: % correspondiente a CEMENTO | FB12: 1 | FI12: % correspondiente a CEMENTO | FK12: 1 | FR12: % correspondiente a CEMENTO | FT12: 1 | GA12: % correspondiente a CEMENTO | GC12: 1 | GE12: 100 | GJ12: % correspondiente a CEMENTO | GL12: 1
N13: Saldo Adeudado CEMENTO | Q13: =+Q29 -> 1.3219444e+08 | AE13: Saldo Adeudado CEMENTO | AG13: =+AG27 -> 1241907.9 | AT13: Saldo Adeudado CEMENTO | AV13: =+AV28 -> 15996516 | BI13: Saldo Adeudado CEMENTO | BK13: =+BK26 -> 53476614 | BX13: Saldo Adeudado CEMENTO | BZ13: =+BZ27+CB24 -> 1098506.4 | CN13: Saldo Adeudado CEMENTO | CP13: =+CP26 -> 1669085.9 | CW13: Saldo Adeudado CEMENTO | CY13: =+CY26 -> 25661049 | DF13: Saldo Adeudado CEMENTO | DH13: =+DH26 -> 9116955.5 | DO13: Saldo Adeudado CEMENTO | DQ13: =+DQ25 -> 1109707.9 | DR13: Transferencia a CERAMIL | DT13: =+DT12*DQ11 -> 3293742.9 | DU13: =+DT13-DQ13 -> 2184035 | EG13: Saldo Adeudado CEMENTO | EI13: =+EI27 -> 2794681.5 | EQ13: Saldo Adeudado CEMENTO | ES13: =+ES26 -> 309433.84 | EZ13: Saldo Adeudado CEMENTO | FB13: =+FB26 -> 309433.84 | FI13: Saldo Adeudado CEMENTO | FK13: =+FK26 -> 309433.84 | FR13: Saldo Adeudado CEMENTO | FT13: =+FT26 -> 309433.84 | GA13: Saldo Adeudado CEMENTO | GC13: =+GC26 -> 388403.55 | GE13: =+GE12/13.8 -> 7.2463768 | GJ13: Saldo Adeudado CEMENTO | GL13: =+GL26 -> 388403.55
N14: Monto desembolsado
N15: Total de Saldo Adeudado | Q15: 2.3061769e+08 | AE15: Total de Saldo Adeudado | AG15: =+AG12*AG13 -> 1241907.9 | AT15: Total de Saldo Adeudado | AV15: =+SUM([3]Consolidado1!$C$241:$C$245) -> 51796168 | AY15: =187920.41+6784.89+626.79 -> 195332.09 | BI15: Total de Saldo Adeudado | BK15: =+BK25 -> 53476614 | BX15: Total de Saldo Adeudado | BZ15: =+BZ13/BZ12 -> 4838608.1 | CN15: Total de Saldo Adeudado | CP15: 1460450.1 | CW15: Total de Saldo Adeudado | CY15: =+SUM([3]Consolidado1!$C$323:$C$328) -> 29810000 | DF15: Total de Saldo Adeudado | DH15: =+DH13/DH12 -> 9174681.5 | DO15: Total de Saldo Adeudado | DQ15: =+SUM([3]Consolidado1!$C$315:$C$319) -> 8467855 | EG15: Total de Saldo Adeudado | EQ15: Total de Saldo Adeudado | ES15: 346343.01 | EZ15: Total de Saldo Adeudado | FB15: 346343.01 | FI15: Total de Saldo Adeudado | FK15: 346343.01 | FR15: Total de Saldo Adeudado | FT15: 346343.01 | GA15: Total de Saldo Adeudado | GC15: 426409.54 | GJ15: Total de Saldo Adeudado | GL15: 426409.54
N16: Total de Intereses Diferidos | Q16: 16433143 | AE16: Total de Intereses Diferidos | AT16: Total de Intereses Diferidos | BI16: Total de Intereses Diferidos | BX16: Total de Intereses Diferidos | CN16: Total de Intereses Diferidos | CW16: Total de Intereses Diferidos | DF16: Total de Intereses Diferidos | DO16: Total de Intereses Diferidos | EG16: Total de Intereses Diferidos | EQ16: Total de Intereses Diferidos | EZ16: Total de Intereses Diferidos | FI16: Total de Intereses Diferidos | FR16: Total de Intereses Diferidos | GA16: Total de Intereses Diferidos | GJ16: Total de Intereses Diferidos
N17: Intereses DIferidos CEMENTO | Q17: =+Q16*Q12 -> 9431010.9 | AE17: Intereses DIferidos CEMENTO | AT17: Intereses DIferidos CEMENTO | BI17: Intereses DIferidos CEMENTO | BX17: Intereses DIferidos CEMENTO | CN17: Intereses DIferidos CEMENTO | CW17: Intereses DIferidos CEMENTO | DF17: Intereses DIferidos CEMENTO | DO17: Intereses DIferidos CEMENTO | EG17: Intereses DIferidos CEMENTO | EQ17: Intereses DIferidos CEMENTO | EZ17: Intereses DIferidos CEMENTO | FI17: Intereses DIferidos CEMENTO | FR17: Intereses DIferidos CEMENTO | GA17: Intereses DIferidos CEMENTO | GJ17: Intereses DIferidos CEMENTO
N18: # Cuotas Intereses Diferidos | Q18: 20 | AE18: # Cuotas Intereses Diferidos | AT18: # Cuotas Intereses Diferidos | BI18: # Cuotas Intereses Diferidos | BX18: # Cuotas Intereses Diferidos | CN18: # Cuotas Intereses Diferidos | CW18: # Cuotas Intereses Diferidos | DF18: # Cuotas Intereses Diferidos | DO18: # Cuotas Intereses Diferidos | EG18: # Cuotas Intereses Diferidos | EQ18: # Cuotas Intereses Diferidos | EZ18: # Cuotas Intereses Diferidos | FI18: # Cuotas Intereses Diferidos | FR18: # Cuotas Intereses Diferidos | GA18: # Cuotas Intereses Diferidos | GJ18: # Cuotas Intereses Diferidos
N19: Amortización Trimenstral 1er Año | Q19: 68600 | AE19: Amortización Trimenstral | AG19: 51840.79 | AT19: Amortización Trimenstral | AV19: 51840.79 | BI19: Amortización Trimenstral | BK19: 51840.79 | BX19: Amortización Trimenstral | BZ19: =+CA26 -> 57736.47 | CN19: Amortización Trimenstral | CW19: Amortización Trimenstral | DF19: Amortización Trimenstral | DO19: Amortización Trimenstral | EG19: Amortización Trimenstral | EQ19: Amortización Trimenstral | EZ19: Amortización Trimenstral | FI19: Amortización Trimenstral | FR19: Amortización Trimenstral | GA19: Amortización Trimenstral | GJ19: Amortización Trimenstral
N20: Amort. Trim 1er año CEMENTO | Q20: =+Q19*Q12 -> 39369.667
N21: Amortización 5to trimestre | Q21: 30369494
A23: N | B23: semana | C23: Dia | D23: Desembolsos | E23: Saldo adeudado | F23: Capital | G23: Intereses | H23: Total Cuota | I23: Por pagar | J23: Entidad | M23: N | N23: Fin mes | O23: Fecha | P23: Desembolsos | Q23: Saldo adeudado | R23: Amortización | S23: Intereses corrientes | T23: Intereses diferidos | U23: Total Cuota | V23: Número de cuota | W23: fecha de pago | X23: dias de mora | Y23: pago a capital | Z23: intereses corrientes | AA23: cuota pagada | AC23: N | AD23: Fin mes | AE23: Fecha | AF23: Desembolsos | AG23: Saldo adeudado | AH23: Amortización | AI23: Intereses corrientes | AJ23: Total Cuota | AK23: Número de cuota | AL23: fecha de pago | AM23: pago a capital | AN23: intereses corrientes | AO23: cuota pagada | AR23: N | AS23: Fin mes | AT23: Fecha | AU23: Desembolsos | AV23: Saldo adeudado | AW23: Amortización | AX23: Intereses corrientes | AY23: Total Cuota | AZ23: Número de cuota | BA23: fecha de pago | BB23: dias de mora | BC23: pago a capital | BD23: intereses corrientes | BE23: cuota pagada | BG23: N | BH23: Fin mes | BI23: Fecha | BJ23: Desembolsos | BK23: Saldo adeudado | BL23: Amortización | BM23: Intereses corrientes | BN23: Interes prorroga y gracia | BO23: Total Cuota | BP23: Número de cuota | BQ23: fecha de pago | BR23: pago a capital | BS23: intereses corrientes | BT23: cuota pagada | BV23: N | BW23: Fin mes | BX23: Fecha | BY23: Desembolsos | BZ23: Saldo adeudado | CA23: Amortización | CB23: Amortización cap diferido | CC23: Intereses corrientes | CD23: Intereses prorroga gracia | CE23: Total Cuota | CF23: Número de cuota | CG23: fecha de pago | CH23: pago a capital | CI23: intereses corrientes | CJ23: cuota pagada | CL23: N | CM23: Fin mes | CN23: Fecha | CO23: Desembolsos | CP23: Saldo adeudado | CQ23: Amortización | CR23: Intereses corrientes | CS23: Total Cuota | CU23: N | CV23: Fin mes | CW23: Fecha | CX23: Desembolsos | CY23: Saldo adeudado | CZ23: Amortización | DA23: Intereses corrientes | DB23: Total Cuota | DD23: N | DE23: Fin mes | DF23: Fecha | DG23: Desembolsos | DH23: Saldo adeudado | DI23: Amortización | DJ23: Intereses corrientes | DK23: Total Cuota | DM23: N | DN23: Fin mes | DO23: Fecha | DP23: Desembolsos | DQ23: Saldo adeudado | DR23: Amortización | DS23: Intereses corrientes | DT23: Total Cuota | EE23: N | EF23: Fin mes | EG23: Fecha | EH23: Desembolsos | EI23: Saldo adeudado | EJ23: Amortización | EK23: Intereses corrientes | EL23: Intereses prorroga gracia | EM23: Total Cuota | EO23: N | EP23: Fin mes | EQ23: Fecha | ER23: Desembolsos | ES23: Saldo adeudado | ET23: Amortización | EU23: Intereses corrientes | EV23: Total Cuota | EX23: N | EY23: Fin mes | EZ23: Fecha | FA23: Desembolsos | FB23: Saldo adeudado | FC23: Amortización | FD23: Intereses corrientes | FE23: Total Cuota | FG23: N | FH23: Fin mes | FI23: Fecha | FJ23: Desembolsos | FK23: Saldo adeudado | FL23: Amortización | FM23: Intereses corrientes | FN23: Total Cuota | FP23: N | FQ23: Fin mes | FR23: Fecha | FS23: Desembolsos | FT23: Saldo adeudado | FU23: Amortización | FV23: Intereses corrientes | FW23: Total Cuota | FY23: N | FZ23: Fin mes | GA23: Fecha | GB23: Desembolsos | GC23: Saldo adeudado | GD23: Amortización | GE23: Intereses corrientes | GF23: Total Cuota | GH23: N | GI23: Fin mes | GJ23: Fecha | GK23: Desembolsos | GL23: Saldo adeudado | GM23: Amortización | GN23: Intereses corrientes | GO23: Total Cuota
F24: =+SUM(F26:F1150) -> 2.4637401e+08 | G24: =+SUM(G26:G1150) -> 48100039 | R24: =+SUM(R30:R1150) -> 1.3219444e+08 | AH24: =+SUM(AH28:AH1150) -> 1241907.9 | AW24: =+SUM(AW29:AW1150) -> 15996516 | BL24: =+SUM(BL29:BL1150) -> 53476614 | CA24: =+SUM(CA28:CA1150) -> 1039256.4 | CB24: =+SUM(CB28:CB1150) -> 59249.999 | CQ24: =+SUM(CQ28:CQ1150) -> 1669085.9 | CZ24: =+SUM(CZ27:CZ1150) -> 25661049 | DI24: =+SUM(DI27:DI1150) -> 9116955.5 | DR24: =+SUM(DR27:DR1150) -> 1109708 | EJ24: =+SUM(EJ27:EJ1150) -> 2794681.5 | ET24: =+SUM(ET27:ET1150) -> 309433.84 | FC24: =+SUM(FC27:FC1150) -> 309433.84 | FL24: =+SUM(FL27:FL1150) -> 309433.84 | FU24: =+SUM(FU27:FU1150) -> 309433.84 | GD24: =+SUM(GD27:GD1150) -> 388403.55 | GM24: =+SUM(GM27:GM1150) -> 388403.55
A25: 0 | B25: =+WEEKNUM(C25,2) -> 35 | C25: 45900 | E25: =+SUM(F26:F1150) -> 2.4637401e+08 | M25: 0 | N25: =+EOMONTH(O25,0) -> 45535 | O25: 45506 | P25: =+Q13 -> 1.3219444e+08 | Q25: 1.3235192e+08 | AC25: 0 | AD25: =+EOMONTH(AE25,0) -> 45716 | AE25: 45712 | AG25: 1345589.5 | AR25: 0 | AS25: =+EOMONTH(AT25,0) -> 45657 | AT25: 45656 | AV25: 15996516 | BG25: 0 | BH25: =+EOMONTH(BI25,0) -> 45747 | BI25: 45736 | BK25: 53476614 | BV25: 0 | BW25: =+EOMONTH(BX25,0) -> 45688 | BX25: 45677 | BZ25: 1154729.4 | CL25: 0 | CM25: =+EOMONTH(CN25,0) -> 45716 | CN25: 45700 | CP25: 1669085.9 | CU25: 0 | CV25: =+EOMONTH(CW25,0) -> 45869 | CW25: 45848 | CY25: 26010061 | DD25: 0 | DE25: =+EOMONTH(DF25,0) -> 45747 | DF25: 45721 | DH25: 9116955.5 | DM25: 0 | DN25: =+EOMONTH(DO25,0) -> 45747 | DO25: 45721 | DQ25: 1109707.9 | EE25: 0 | EF25: =+EOMONTH(EG25,0) -> 45657 | EG25: 45657 | EI25: 2794681.5 | EO25: 0 | EP25: =+EOMONTH(EQ25,0) -> 45747 | EQ25: =+EQ26-90 -> 45742 | ES25: 346343.01 | EX25: 0 | EY25: =+EOMONTH(EZ25,0) -> 45747 | EZ25: =+EZ26-90 -> 45742 | FB25: 346343.01 | FG25: 0 | FH25: =+EOMONTH(FI25,0) -> 45747 | FI25: =+FI26-90 -> 45742 | FK25: 346343.01 | FP25: 0 | FQ25: =+EOMONTH(FR25,0) -> 45747 | FR25: =+FR26-90 -> 45742 | FT25: 346343.01 | FY25: 0 | FZ25: =+EOMONTH(GA25,0) -> 45747 | GA25: =+GA26-90 -> 45724 | GC25: 426409.54 | GH25: 0 | GI25: =+EOMONTH(GJ25,0) -> 45747 | GJ25: 45724 | GL25: 426409.54
A26: 1 | B26: =+WEEKNUM(C26,2) -> 40 | C26: =+EOMONTH(C25,1) -> 45930 | E26: =+E25+D26-F26 -> 2.457966e+08 | F26: =+SUMIF(N:N,C26,R:R)+SUMIF(AD:AD,C26,AH:AH)+SUMIF(AS:AS,C26,AW:AW)+SUMIF(BH:BH,C26,BL:BL)+SUMIF(BW:BW,C26,CA:CA)+SUMIF(BW:BW,C26,CB:CB)+SUMIF(CM:CM,C26,CQ:CQ)+SUMIF(CV:CV,C26,CZ:CZ)+SUMIF(DE:DE,C26,DI:DI)+SUMIF(DN:DN,C26,DR:DR)+SUMIF(DW:DW,C26,EA:EA)+SUMIF(EF:EF,C26,EJ:EJ)+SUMIF(EP:EP,C26,ET:ET)+SUMIF(EY:EY,C26,FC:FC)+SUMIF(FH:FH,C26,FL:FL)+SUMIF(FQ:FQ,C26,FU:FU)+SUMIF(FZ:FZ,C26,GD:GD)+SUMIF(GI:GI,C26,GM:GM) -> 577412.41 | G26: =+SUMIF(N:N,C26,S:S)+SUMIF(N:N,C26,T:T)+SUMIF(AD:AD,C26,AI:AI)+SUMIF(AS:AS,C26,AX:AX)+SUMIF(BH:BH,C26,BM:BM)+SUMIF(BW:BW,C26,CD:CD)+SUMIF(BW:BW,C26,CC:CC)+SUMIF(CM:CM,C26,CR:CR)+SUMIF(CV:CV,C26,DA:DA)+SUMIF(DE:DE,C26,DJ:DJ)+SUMIF(DN:DN,C26,DS:DS)+SUMIF(DX:DX,C26,EB:EB)+SUMIF(EG:EG,C26,EK:EK)+SUMIF(EP:EP,C26,EU:EU)+SUMIF(EY:EY,C26,FD:FD)+SUMIF(FH:FH,C26,FM:FM)+SUMIF(FQ:FQ,C26,FV:FV)+SUMIF(FZ:FZ,C26,GE:GE)+SUMIF(GI:GI,C26,GN:GN) -> 1126666.7 | H26: =+SUM(F26:G26) -> 1704079.2 | M26: 1 | N26: =+EOMONTH(O26,0) -> 45626 | O26: 45611 | Q26: =+Q25-R26 -> 1.3231255e+08 | R26: =+$Q$20 -> 39369.667 | S26: =+Q25*Q$5*(O26-O25)/360 -> 2316158.6 | T26: =+$Q$17/$Q$18 -> 471550.55 | U26: =+SUM(R26:T26) -> 2827078.8 | AC26: 1 | AD26: =+EOMONTH(AE26,0) -> 45808 | AE26: 45779 | AG26: =+AG25+AF26-AH26 -> 1293748.7 | AH26: =+AG19 -> 51840.79 | AI26: =+AG25*AG$5*(AE26-AE25)/360 -> 13773.604 | AJ26: =+SUM(AH26:AI26) -> 65614.394 | AK26: 1 | AL26: 45796 | AM26: =+AH26 -> 51840.79 | AN26: =+AG25*AG$5*(AL26-AE25)/360 -> 17268.399 | AO26: =+AN26+AM26 -> 69109.189 | AR26: 1 | AS26: =+EOMONTH(AT26,0) -> 45716 | AT26: 45708 | AV26: 15996516 | AW26: 0 | AX26: =+AV25*AV$5*(AT26-AT25)/360 -> 138636.47 | AY26: =+SUM(AW26:AX26) -> 138636.47 | AZ26: 1 | BA26: 45744 | BB26: =+BA26-AT26 -> 36 | BC26: =+AW26 -> 0 | BD26: =+AV25*AV$5*(BA26-AT25)/360 -> 234615.57 | BE26: =+BD26+BC26 -> 234615.57 | BG26: 1 | BH26: =+EOMONTH(BI26,0) -> 45838 | BI26: 45828 | BK26: =+BK25+BJ26-BL26 -> 53476614 | BL26: 0 | BM26: =+BK25*BK$5*(BI26-BI25)/360 -> 819974.75 | BN26: 82616.23 | BO26: =+SUM(BL26:BN26) -> 902590.98 | BP26: 1 | BQ26: 45828 | BR26: =+BL26 -> 0 | BS26: =+BK25*BK$5*(BQ26-BI25)/360 -> 819974.75 | BT26: =+BS26+BR26+BN26 -> 902590.98 | BV26: 1 | BW26: =+EOMONTH(BX26,0) -> 45716 | BX26: 45702 | BZ26: =+BZ25+BY26-CA26 -> 1096992.9 | CA26: 57736.47 | CB26: 0 | CC26: =+BZ25*BZ$5*(BX26-BX25)/360 -> 4811.3725 | CD26: 1642.8395 | CE26: =+SUM(CA26:CD26) -> 64190.682 | CF26: 1 | CG26: 45702 | CH26: =+CA26 -> 57736.47 | CI26: =+BZ25*BZ$5*(CG26-BX25)/360 -> 4811.3725 | CJ26: =+CI26+CH26+CD26 -> 64190.682 | CL26: 1 | CM26: =+EOMONTH(CN26,0) -> 45838 | CN26: 45822 | CP26: =+CP25+CO26-CQ26 -> 1669085.9 | CQ26: 0 | CR26: 29209.003 | CS26: =+SUM(CQ26:CR26) -> 29209.003 | CU26: 1 | CV26: =+EOMONTH(CW26,0) -> 45900 | CW26: 45879 | CY26: =+CY25+CX26-CZ26 -> 25661049 | CZ26: 349011.21 | DA26: =+CY25*CY$5*(CW26-CW25)/360 -> 134385.31 | DB26: =+SUM(CZ26:DA26) -> 483396.52 | DD26: 1 | DE26: =+EOMONTH(DF26,0) -> 45838 | DF26: 45838 | DH26: =+DH25+DG26-DI26 -> 9116955.5 | DI26: 0 | DJ26: 138152.48 | DK26: =+SUM(DI26:DJ26) -> 138152.48 | DM26: 1 | DN26: =+EOMONTH(DO26,0) -> 45838 | DO26: 45838 | DQ26: =+DQ25-DR26 -> 1109707.9 | DR26: 0 | DS26: 16421.12 | DT26: =+SUM(DR26:DS26) -> 16421.12 | EE26: 1 | EF26: =+EOMONTH(EG26,0) -> 45747 | EG26: 45721 | EI26: =+EI25+EH26-EJ26 -> 2794681.5 | EJ26: 0 | EK26: 17114.156 | EL26: 86.4 | EM26: =+SUM(EJ26:EL26) -> 17200.556 | EO26: 1 | EP26: =+EOMONTH(EQ26,0) -> 45838 | EQ26: 45832 | ES26: =+ES25-ET26 -> 309433.84 | ET26: 36909.17 | EU26: 4285.87 | EV26: =+SUM(ET26:EU26) -> 41195.04 | EX26: 1 | EY26: =+EOMONTH(EZ26,0) -> 45838 | EZ26: 45832 | FB26: =+FB25-FC26 -> 309433.84 | FC26: 36909.17 | FD26: 4285.87 | FE26: =+SUM(FC26:FD26) -> 41195.04 | FG26: 1 | FH26: =+EOMONTH(FI26,0) -> 45838 | FI26: 45832 | FK26: =+FK25-FL26 -> 309433.84 | FL26: 36909.17 | FM26: 4285.87 | FN26: =+SUM(FL26:FM26) -> 41195.04 | FP26: 1 | FQ26: =+EOMONTH(FR26,0) -> 45838 | FR26: 45832 | FT26: =+FT25-FU26 -> 309433.84 | FU26: 36909.17 | FV26: 4285.87 | FW26: =+SUM(FU26:FV26) -> 41195.04 | FY26: 1 | FZ26: =+EOMONTH(GA26,0) -> 45838 | GA26: 45814 | GC26: =+GC25-GD26 -> 388403.55 | GD26: 38005.99 | GE26: 5069.14 | GF26: =+SUM(GD26:GE26) -> 43075.13 | GH26: 1 | GI26: =+EOMONTH(GJ26,0) -> 45838 | GJ26: 45814 | GL26: 388403.55 | GM26: 38005.99 | GN26: 5069.14 | GO26: 43075.13
A27: 2 | B27: =+WEEKNUM(C27,2) -> 44 | C27: =+EOMONTH(C26,1) -> 45961 | E27: =+E26+D27-F27 -> 2.4538703e+08 | F27: =+SUMIF(N:N,C27,R:R)+SUMIF(AD:AD,C27,AH:AH)+SUMIF(AS:AS,C27,AW:AW)+SUMIF(BH:BH,C27,BL:BL)+SUMIF(BW:BW,C27,CA:CA)+SUMIF(BW:BW,C27,CB:CB)+SUMIF(CM:CM,C27,CQ:CQ)+SUMIF(CV:CV,C27,CZ:CZ)+SUMIF(DE:DE,C27,DI:DI)+SUMIF(DN:DN,C27,DR:DR)+SUMIF(DW:DW,C27,EA:EA)+SUMIF(EF:EF,C27,EJ:EJ)+SUMIF(EP:EP,C27,ET:ET)+SUMIF(EY:EY,C27,FC:FC)+SUMIF(FH:FH,C27,FL:FL)+SUMIF(FQ:FQ,C27,FU:FU)+SUMIF(FZ:FZ,C27,GD:GD)+SUMIF(GI:GI,C27,GM:GM) -> 409569.11 | G27: =+SUMIF(N:N,C27,S:S)+SUMIF(N:N,C27,T:T)+SUMIF(AD:AD,C27,AI:AI)+SUMIF(AS:AS,C27,AX:AX)+SUMIF(BH:BH,C27,BM:BM)+SUMIF(BW:BW,C27,CD:CD)+SUMIF(BW:BW,C27,CC:CC)+SUMIF(CM:CM,C27,CR:CR)+SUMIF(CV:CV,C27,DA:DA)+SUMIF(DE:DE,C27,DJ:DJ)+SUMIF(DN:DN,C27,DS:DS)+SUMIF(DX:DX,C27,EB:EB)+SUMIF(EG:EG,C27,EK:EK)+SUMIF(EP:EP,C27,EU:EU)+SUMIF(EY:EY,C27,FD:FD)+SUMIF(FH:FH,C27,FM:FM)+SUMIF(FQ:FQ,C27,FV:FV)+SUMIF(FZ:FZ,C27,GE:GE)+SUMIF(GI:GI,C27,GN:GN) -> 161719.77 | H27: =+SUM(F27:G27) -> 571288.88 | M27: 2 | N27: =+EOMONTH(O27,0) -> 45716 | O27: 45703 | Q27: =+Q26-R27 -> 1.3227318e+08 | R27: =+$Q$20 -> 39369.667 | S27: =+Q26*Q$5*(O27-O26)/360 -> 2028792.4 | T27: =+$Q$17/$Q$18 -> 471550.55 | U27: =+SUM(R27:T27) -> 2539712.7 | W27: 45703 | AC27: 2 | AD27: =+EOMONTH(AE27,0) -> 45900 | AE27: 45871 | AG27: =+AG26+AF27-AH27 -> 1241907.9 | AH27: =+AH26 -> 51840.79 | AI27: =+AG26*AG$5*(AE27-AE26)/360 -> 18184.357 | AJ27: =+SUM(AH27:AI27) -> 70025.147 | AK27: 2 | AL27: =+TODAY() -> 46090 | AM27: =+AH27 -> 51840.79 | AN27: =+AG26*AG$5*(AL27-AL26)/360 -> 58110.88 | AO27: =+AN27+AM27 -> 109951.67 | AR27: 2 | AS27: =+EOMONTH(AT27,0) -> 45808 | AT27: 45797 | AV27: =+AV26+AU27-AW27 -> 15996516 | AW27: 0 | AX27: =+AV26*AV$5*(AT27-AT26)/360 -> 237281.65 | AY27: =+SUM(AW27:AX27) -> 237281.65 | AZ27: 2 | BA27: 45838 | BB27: =+BA27-AT27 -> 41 | BC27: =+AW27 -> 0 | BD27: =+AV26*AV$5*(BA27-BA26)/360 -> 250612.08 | BE27: =+BD27+BC27 -> 250612.08 | BG27: 2 | BH27: =+EOMONTH(BI27,0) -> 45930 | BI27: 45920 | BK27: =+BK26+BJ27-BL27 -> 53476614 | BL27: 0 | BM27: =+BK26*BK$5*(BI27-BI26)/360 -> 819974.75 | BN27: 82616.23 | BO27: =+SUM(BL27:BN27) -> 902590.98 | BP27: 2 | BQ27: 45920 | BR27: =+BL27 -> 0 | BS27: =+BK26*BK$5*(BQ27-BQ26)/360 -> 819974.75 | BT27: =+BS27+BR27+BN27 -> 902590.98 | BV27: 2 | BW27: =+EOMONTH(BX27,0) -> 45869 | BX27: 45858 | BZ27: =+BZ26+BY27-CA27 -> 1039256.4 | CA27: 57736.47 | CB27: 2821.4285 | CC27: =+BZ26*BZ$5*(BX27-BX26)/360 -> 28521.816 | CD27: 1642.8395 | CE27: =+SUM(CA27:CD27) -> 90722.554 | CF27: 2 | CG27: 45866 | CH27: =+CA27 -> 57736.47 | CI27: =+BZ26*BZ$5*(CG27-CG26)/360 -> 29984.473 | CJ27: =+CI27+CH27+CD27 -> 89363.783 | CL27: 2 | CM27: =+EOMONTH(CN27,0) -> 45930 | CN27: 45914 | CP27: =+CP26+CO27-CQ27 -> 1669085.9 | CQ27: 0 | CR27: 22393.569 | CS27: =+SUM(CQ27:CR27) -> 22393.569 | CU27: 2 | CV27: =+EOMONTH(CW27,0) -> 45930 | CW27: 45910 | CY27: =+CY26+CX27-CZ27 -> 25312038 | CZ27: 349011.21 | DA27: =+CY26*CY$5*(CW27-CW26)/360 -> 132582.09 | DB27: =+SUM(CZ27:DA27) -> 481593.3 | DD27: 2 | DE27: =+EOMONTH(DF27,0) -> 45930 | DF27: 45925 | DH27: =+DH26+DG27-DI27 -> 9116955.5 | DI27: 0 | DJ27: 127789.32 | DK27: =+SUM(DI27:DJ27) -> 127789.32 | DM27: 2 | DN27: =+EOMONTH(DO27,0) -> 45961 | DO27: 45936 | DQ27: =+DQ26-DR27 -> 1109707.9 | DR27: 0 | DS27: =+DQ26*(DO27-DO26)*$DQ$5/360 -> 17581.472 | DT27: =+SUM(DR27:DS27) -> 17581.472 | EE27: 2 | EF27: =+EOMONTH(EG27,0) -> 45838 | EG27: 45838 | EI27: =+EI26+EH27-EJ27 -> 2794681.5 | EJ27: 0 | EK27: 38370.47 | EL27: 19844.48 | EM27: =+SUM(EJ27:EL27) -> 58214.95 | EO27: 2 | EP27: =+EOMONTH(EQ27,0) -> 45930 | EQ27: 45922 | ES27: =+ES26-ET27 -> 271740.35 | ET27: 37693.49 | EU27: 3732.23 | EV27: =+SUM(ET27:EU27) -> 41425.72 | EX27: 2 | EY27: =+EOMONTH(EZ27,0) -> 45930 | EZ27: 45922 | FB27: =+FB26-FC27 -> 271740.35 | FC27: 37693.49 | FD27: 3732.23 | FE27: =+SUM(FC27:FD27) -> 41425.72 | FG27: 2 | FH27: =+EOMONTH(FI27,0) -> 45930 | FI27: 45922 | FK27: =+FK26-FL27 -> 271740.35 | FL27: 37693.49 | FM27: 3732.23 | FN27: =+SUM(FL27:FM27) -> 41425.72 | FP27: 2 | FQ27: =+EOMONTH(FR27,0) -> 45930 | FR27: 45922 | FT27: =+FT26-FU27 -> 271740.35 | FU27: 37693.49 | FV27: 3732.23 | FW27: =+SUM(FU27:FV27) -> 41425.72 | FY27: 2 | FZ27: =+EOMONTH(GA27,0) -> 45930 | GA27: 45904 | GC27: =+GC26-GD27 -> 349589.93 | GD27: 38813.62 | GE27: 4499.05 | GF27: =+SUM(GD27:GE27) -> 43312.67 | GH27: 2 | GI27: =+EOMONTH(GJ27,0) -> 45930 | GJ27: 45904 | GL27: 349589.93 | GM27: 38813.62 | GN27: 4499.05 | GO27: 43312.67
A28: 3 | B28: =+WEEKNUM(C28,2) -> 48 | C28: =+EOMONTH(C27,1) -> 45991 | E28: =+E27+D28-F28 -> 2.1461668e+08 | F28: =+SUMIF(N:N,C28,R:R)+SUMIF(AD:AD,C28,AH:AH)+SUMIF(AS:AS,C28,AW:AW)+SUMIF(BH:BH,C28,BL:BL)+SUMIF(BW:BW,C28,CA:CA)+SUMIF(BW:BW,C28,CB:CB)+SUMIF(CM:CM,C28,CQ:CQ)+SUMIF(CV:CV,C28,CZ:CZ)+SUMIF(DE:DE,C28,DI:DI)+SUMIF(DN:DN,C28,DR:DR)+SUMIF(DW:DW,C28,EA:EA)+SUMIF(EF:EF,C28,EJ:EJ)+SUMIF(EP:EP,C28,ET:ET)+SUMIF(EY:EY,C28,FC:FC)+SUMIF(FH:FH,C28,FL:FL)+SUMIF(FQ:FQ,C28,FU:FU)+SUMIF(FZ:FZ,C28,GD:GD)+SUMIF(GI:GI,C28,GM:GM) -> 30770346 | G28: =+SUMIF(N:N,C28,S:S)+SUMIF(N:N,C28,T:T)+SUMIF(AD:AD,C28,AI:AI)+SUMIF(AS:AS,C28,AX:AX)+SUMIF(BH:BH,C28,BM:BM)+SUMIF(BW:BW,C28,CD:CD)+SUMIF(BW:BW,C28,CC:CC)+SUMIF(CM:CM,C28,CR:CR)+SUMIF(CV:CV,C28,DA:DA)+SUMIF(DE:DE,C28,DJ:DJ)+SUMIF(DN:DN,C28,DS:DS)+SUMIF(DX:DX,C28,EB:EB)+SUMIF(EG:EG,C28,EK:EK)+SUMIF(EP:EP,C28,EU:EU)+SUMIF(EY:EY,C28,FD:FD)+SUMIF(FH:FH,C28,FM:FM)+SUMIF(FQ:FQ,C28,FV:FV)+SUMIF(FZ:FZ,C28,GE:GE)+SUMIF(GI:GI,C28,GN:GN) -> 2890243.2 | H28: =+SUM(F28:G28) -> 33660590 | I28: =+AA28 -> 9042540.4 | J28: Fideicomiso | M28: 3 | N28: =+EOMONTH(O28,0) -> 45808 | O28: 45792 | Q28: =+Q27-R28 -> 1.3223381e+08 | R28: =+$Q$20 -> 39369.667 | S28: =+Q27*Q$5*(O28-O27)/360 -> 1962052.2 | T28: =+$Q$17/$Q$18 -> 471550.55 | U28: =+SUM(R28:T28) -> 2472972.4 | V28: 3 | W28: =+TODAY() -> 46090 | X28: =+W28-W27 -> 387 | Y28: =+R28 -> 39369.667 | Z28: =+Q27*Q$5*(W28-O27)/360 -> 8531620.2 | AA28: =+Z28+Y28+T28 -> 9042540.4 | AC28: 3 | AD28: =+EOMONTH(AE28,0) -> 45991 | AE28: 45963 | AG28: =+AG27+AF28-AH28 -> 1190067.1 | AH28: =+AH27 -> 51840.79 | AI28: =+AG27*AG$5*(AE28-AE27)/360 -> 17455.706 | AJ28: =+SUM(AH28:AI28) -> 69296.496 | AR28: 3 | AS28: =+EOMONTH(AT28,0) -> 45900 | AT28: 45889 | AV28: =+AV27+AU28-AW28 -> 15996516 | AW28: 0 | AX28: =+AV27*AV$5*(AT28-AT27)/360 -> 245279.91 | AY28: =+SUM(AW28:AX28) -> 245279.91 | AZ28: 3 | BA28: =+TODAY() -> 46090 | BB28: =+BA28-AT28 -> 201 | BC28: =+AW28 -> 0 | BD28: =+AV27*AV$5*(BA28-BA27)/360 -> 671853.67 | BE28: =+BD28+BC28 -> 671853.67 | BG28: 3 | BH28: =+EOMONTH(BI28,0) -> 46022 | BI28: 46011 | BK28: =+BK27+BJ28-BL28 -> 53476614 | BL28: 0 | BM28: =+BK27*BK$5*(BI28-BI27)/360 -> 811061.98 | BN28: 82616.23 | BO28: =+SUM(BL28:BN28) -> 893678.21 | BV28: 3 | BW28: =+EOMONTH(BX28,0) -> 45961 | BX28: 45950 | BZ28: =+BZ27+BY28-CA28 -> 981519.98 | CA28: 57736.47 | CB28: 2821.4285 | CC28: =+BZ27*BZ$5*(BX28-BX27)/360 -> 15935.266 | CD28: 1642.8395 | CE28: =+SUM(CA28:CD28) -> 78136.004 | CL28: 3 | CM28: =+EOMONTH(CN28,0) -> 46022 | CN28: 46005 | CP28: =+CP27+CO28-CQ28 -> 1564768 | CQ28: 104317.86 | CR28: 22150.161 | CS28: =+SUM(CQ28:CR28) -> 126468.02 | CU28: 3 | CV28: =+EOMONTH(CW28,0) -> 45961 | CW28: 45940 | CY28: =+CY27+CX28-CZ28 -> 24963027 | CZ28: 349011.21 | DA28: =+CY27*CY$5*(CW28-CW27)/360 -> 126560.19 | DB28: =+SUM(CZ28:DA28) -> 475571.4 | DD28: 3 | DE28: =+EOMONTH(DF28,0) -> 46022 | DF28: 46017 | DH28: =+DH27+DG28-DI28 -> 9116955.5 | DI28: 0 | DJ28: 135133.54 | DK28: =+SUM(DI28:DJ28) -> 135133.54 | DM28: 3 | DN28: =+EOMONTH(DO28,0) -> 46053 | DO28: 46027 | DQ28: =+DQ27-DR28 -> 1109707.9 | DR28: 0 | DS28: =+DQ27*(DO28-DO27)*$DQ$5/360 -> 16325.652 | DT28: =+SUM(DR28:DS28) -> 16325.652 | EE28: 3 | EF28: =+EOMONTH(EG28,0) -> 45930 | EG28: 45925 | EI28: =+EI27+EH28-EJ28 -> 2794681.5 | EJ28: 0 | EK28: 17027.76 | EM28: =+SUM(EJ28:EL28) -> 17027.76 | EO28: 3 | EP28: =+EOMONTH(EQ28,0) -> 46022 | EQ28: 46012 | ES28: =+ES27-ET28 -> 233245.87 | ET28: 38494.48 | EU28: 3166.83 | EV28: =+SUM(ET28:EU28) -> 41661.31 | EX28: 3 | EY28: =+EOMONTH(EZ28,0) -> 46022 | EZ28: 46012 | FB28: =+FB27-FC28 -> 233245.87 | FC28: 38494.48 | FD28: 3166.83 | FE28: =+SUM(FC28:FD28) -> 41661.31 | FG28: 3 | FH28: =+EOMONTH(FI28,0) -> 46022 | FI28: 46012 | FK28: =+FK27-FL28 -> 233245.87 | FL28: 38494.48 | FM28: 3166.83 | FN28: =+SUM(FL28:FM28) -> 41661.31 | FP28: 3 | FQ28: =+EOMONTH(FR28,0) -> 46022 | FR28: 46012 | FT28: =+FT27-FU28 -> 233245.87 | FU28: 38494.48 | FV28: 3166.83 | FW28: =+SUM(FU28:FV28) -> 41661.31 | FY28: 3 | FZ28: =+EOMONTH(GA28,0) -> 46022 | GA28: 45994 | GC28: =+GC27-GD28 -> 309951.52 | GD28: 39638.41 | GE28: 3916.84 | GF28: =+SUM(GD28:GE28) -> 43555.25 | GH28: 3 | GI28: =+EOMONTH(GJ28,0) -> 46022 | GJ28: 45994 | GL28: 309951.52 | GM28: 39638.41 | GN28: 3916.84 | GO28: 43555.25
A29: 4 | B29: =+WEEKNUM(C29,2) -> 53 | C29: =+EOMONTH(C28,1) -> 46022 | E29: =+E28+D29-F29 -> 2.139301e+08 | F29: =+SUMIF(N:N,C29,R:R)+SUMIF(AD:AD,C29,AH:AH)+SUMIF(AS:AS,C29,AW:AW)+SUMIF(BH:BH,C29,BL:BL)+SUMIF(BW:BW,C29,CA:CA)+SUMIF(BW:BW,C29,CB:CB)+SUMIF(CM:CM,C29,CQ:CQ)+SUMIF(CV:CV,C29,CZ:CZ)+SUMIF(DE:DE,C29,DI:DI)+SUMIF(DN:DN,C29,DR:DR)+SUMIF(DW:DW,C29,EA:EA)+SUMIF(EF:EF,C29,EJ:EJ)+SUMIF(EP:EP,C29,ET:ET)+SUMIF(EY:EY,C29,FC:FC)+SUMIF(FH:FH,C29,FL:FL)+SUMIF(FQ:FQ,C29,FU:FU)+SUMIF(FZ:FZ,C29,GD:GD)+SUMIF(GI:GI,C29,GM:GM) -> 686583.81 | G29: =+SUMIF(N:N,C29,S:S)+SUMIF(N:N,C29,T:T)+SUMIF(AD:AD,C29,AI:AI)+SUMIF(AS:AS,C29,AX:AX)+SUMIF(BH:BH,C29,BM:BM)+SUMIF(BW:BW,C29,CD:CD)+SUMIF(BW:BW,C29,CC:CC)+SUMIF(CM:CM,C29,CR:CR)+SUMIF(CV:CV,C29,DA:DA)+SUMIF(DE:DE,C29,DJ:DJ)+SUMIF(DN:DN,C29,DS:DS)+SUMIF(DX:DX,C29,EB:EB)+SUMIF(EG:EG,C29,EK:EK)+SUMIF(EP:EP,C29,EU:EU)+SUMIF(EY:EY,C29,FD:FD)+SUMIF(FH:FH,C29,FM:FM)+SUMIF(FQ:FQ,C29,FV:FV)+SUMIF(FZ:FZ,C29,GE:GE)+SUMIF(GI:GI,C29,GN:GN) -> 1111916.8 | H29: =+SUM(F29:G29) -> 1798500.6 | M29: 4 | N29: =+EOMONTH(O29,0) -> 45900 | O29: 45884 | Q29: =+Q28-R29 -> 1.3219444e+08 | R29: =+$Q$20 -> 39369.667 | S29: =+Q28*Q$5*(O29-O28)/360 -> 2027585.1 | T29: =+$Q$17/$Q$18 -> 471550.55 | U29: =+SUM(R29:T29) -> 2538505.3 | V29: 4 | W29: =+TODAY() -> 46090 | Y29: =+R29 -> 39369.667 | AA29: =+Y29 -> 39369.667 | AC29: 4 | AD29: =+EOMONTH(AE29,0) -> 46081 | AE29: 46055 | AG29: =+AG28+AF29-AH29 -> 1138226.3 | AH29: =+AH28 -> 51840.79 | AI29: =+AG28*AG$5*(AE29-AE28)/360 -> 16727.055 | AJ29: =+SUM(AH29:AI29) -> 68567.845 | AR29: 4 | AS29: =+EOMONTH(AT29,0) -> 45991 | AT29: 45981 | AV29: =+AV28+AU29-AW29 -> 15996516 | AW29: 0 | AX29: =+AV28*AV$5*(AT29-AT28)/360 -> 245279.91 | AY29: =+SUM(AW29:AX29) -> 245279.91 | BG29: 4 | BH29: =+EOMONTH(BI29,0) -> 46112 | BI29: 46101 | BK29: =+BK28+BJ29-BL29 -> 53476614 | BL29: 0 | BM29: =+BK28*BK$5*(BI29-BI28)/360 -> 802149.21 | BN29: 82616.23 | BO29: =+SUM(BL29:BN29) -> 884765.44 | BV29: 4 | BW29: =+EOMONTH(BX29,0) -> 46053 | BX29: 46042 | BZ29: =+BZ28+BY29-CA29 -> 923783.51 | CA29: 57736.47 | CB29: 2821.4285 | CC29: =+BZ28*BZ$5*(BX29-BX28)/360 -> 15049.973 | CD29: 1642.8395 | CE29: =+SUM(CA29:CD29) -> 77250.711 | CL29: 4 | CM29: =+EOMONTH(CN29,0) -> 46112 | CN29: 46095 | CP29: =+CP28+CO29-CQ29 -> 1460450.1 | CQ29: 104317.86 | CR29: 20341.984 | CS29: =+SUM(CQ29:CR29) -> 124659.84 | CU29: 4 | CV29: =+EOMONTH(CW29,0) -> 45991 | CW29: 45971 | CY29: =+CY28+CX29-CZ29 -> 24614016 | CZ29: 349011.21 | DA29: =+CY28*CY$5*(CW29-CW28)/360 -> 128975.64 | DB29: =+SUM(CZ29:DA29) -> 477986.85 | DD29: 4 | DE29: =+EOMONTH(DF29,0) -> 46112 | DF29: 46107 | DH29: =+DH28+DG29-DI29 -> 9102050 | DI29: 14905.56 | DJ29: 132195.85 | DK29: =+SUM(DI29:DJ29) -> 147101.41 | DM29: 4 | DN29: =+EOMONTH(DO29,0) -> 46142 | DO29: 46118 | DQ29: =+DQ28-DR29 -> 1107774.2 | DR29: 1933.63 | DS29: =+DQ28*(DO29-DO28)*$DQ$5/360 -> 16325.652 | DT29: =+SUM(DR29:DS29) -> 18259.282 | EE29: 4 | EF29: =+EOMONTH(EG29,0) -> 46022 | EG29: 46017 | EI29: =+EI28+EH29-EJ29 -> 2794681.5 | EJ29: 0 | EK29: 18006.37 | EL29: 0 | EM29: =+SUM(EJ29:EL29) -> 18006.37 | EO29: 4 | EP29: =+EOMONTH(EQ29,0) -> 46112 | EQ29: 46102 | ES29: =+ES28-ET29 -> 193933.38 | ET29: 39312.49 | EU29: 2589.41 | EV29: =+SUM(ET29:EU29) -> 41901.9 | EX29: 4 | EY29: =+EOMONTH(EZ29,0) -> 46112 | EZ29: 46102 | FB29: =+FB28-FC29 -> 193933.38 | FC29: 39312.49 | FD29: 2589.41 | FE29: =+SUM(FC29:FD29) -> 41901.9 | FG29: 4 | FH29: =+EOMONTH(FI29,0) -> 46112 | FI29: 46102 | FK29: =+FK28-FL29 -> 193933.38 | FL29: 39312.49 | FM29: 2589.41 | FN29: =+SUM(FL29:FM29) -> 41901.9 | FP29: 4 | FQ29: =+EOMONTH(FR29,0) -> 46112 | FR29: 46102 | FT29: =+FT28-FU29 -> 193933.38 | FU29: 39312.49 | FV29: 2589.41 | FW29: =+SUM(FU29:FV29) -> 41901.9 | FY29: 4 | FZ29: =+EOMONTH(GA29,0) -> 46112 | GA29: 46084 | GC29: =+GC28-GD29 -> 269470.8 | GD29: 40480.72 | GE29: 3322.26 | GF29: =+SUM(GD29:GE29) -> 43802.98 | GH29: 4 | GI29: =+EOMONTH(GJ29,0) -> 46112 | GJ29: 46084 | GL29: 269470.8 | GM29: 40480.72 | GN29: 3322.26 | GO29: 43802.98
