Workbook

Sheet Caracteristicas
A1: Nro de la operación | B1: Entidad | C1: Cod. Entidad | D1: Moneda | E1: Tasa | F1: Periodicidad | G1: desembolso | H1: vencimiento | I1: Plazo (dias) | J1: Monto Inicial | K1: Saldo a capital | L1: % adeudado por Cemento | M1: Saldo a capital Cemento | N1: Monto garantia | O1: Garantias | P1: Covenants | Q1: capital en mora | R1: interes en mora | S1: saldo ajustado
A2: 3167401 | B2: =+HLOOKUP($A2,'Obligaciones financieras'!$Q$1:$HV$21,COLUMNS($A2:B2),FALSE) -> Fideicomiso - Banco Unión | C2: =+HLOOKUP($A2,'Obligaciones financieras'!$Q$1:$HV$21,COLUMNS($A2:C2),FALSE) -> FID - BUN | D2: =+HLOOKUP($A2,'Obligaciones financieras'!$Q$1:$HV$21,COLUMNS($A2:D2),FALSE) -> Bolivanos | E2: =+HLOOKUP($A2,'Obligaciones financieras'!$Q$1:$HV$21,COLUMNS($A2:E2),FALSE)*100 -> 6 | F2: =+HLOOKUP($A2,'Obligaciones financieras'!$Q$1:$HV$21,COLUMNS($A2:F2),FALSE) -> Trimestral | G2: 45463 | H2: =+HLOOKUP($A2,'Obligaciones financieras'!$Q$1:$HV$21,COLUMNS($A2:H2),FALSE) -> 48248 | I2: =8*365 -> 2920 | J2: 2.3061769e+08 | K2: =+HLOOKUP($A2,'Obligaciones financieras'!$Q$1:$HV$21,COLUMNS($A2:K2),FALSE) -> 2.3034329e+08 | L2: =+HLOOKUP($A2,'Obligaciones financieras'!$Q$1:$HV$21,COLUMNS($A2:L2),FALSE)*100 -> 57.390185 | M2: =+HLOOKUP($A2,'Obligaciones financieras'!$Q$1:$HV$21,COLUMNS($A2:M2),FALSE) -> 1.3219444e+08 | N2: =+Garantias!R2 -> 2.3762982e+08 | O2: - Existencias de mercaderia - Prendaria | Q2: =SUM('3167401'!C3:C6) -> 157478.67 | R2: 0 | S2: 0
A3: 2767412 | B3: =+HLOOKUP($A3,'Obligaciones financieras'!$Q$1:$HV$21,COLUMNS($A3:B3),FALSE) -> Banco Unión | C3: =+HLOOKUP($A3,'Obligaciones financieras'!$Q$1:$HV$21,COLUMNS($A3:C3),FALSE) -> BUN | D3: =+HLOOKUP($A3,'Obligaciones financieras'!$Q$1:$HV$21,COLUMNS($A3:D3),FALSE) -> Bolivanos | E3: =+HLOOKUP($A3,'Obligaciones financieras'!$Q$1:$HV$21,COLUMNS($A3:E3),FALSE)*100 -> 5.5 | F3: =+HLOOKUP($A3,'Obligaciones financieras'!$Q$1:$HV$21,COLUMNS($A3:F3),FALSE) -> Trimestral | H3: =+HLOOKUP($A3,'Obligaciones financieras'!$Q$1:$HV$21,COLUMNS($A3:H3),FALSE) -> 48058 | K3: =+HLOOKUP($A3,'Obligaciones financieras'!$Q$1:$HV$21,COLUMNS($A3:K3),FALSE) -> 1241907.9 | L3: =+HLOOKUP($A3,'Obligaciones financieras'!$Q$1:$HV$21,COLUMNS($A3:L3),FALSE)*100 -> 100 | M3: =+HLOOKUP($A3,'Obligaciones financieras'!$Q$1:$HV$21,COLUMNS($A3:M3),FALSE) -> 1241907.9
A4: 2764418 | B4: =+HLOOKUP($A4,'Obligaciones financieras'!$Q$1:$HV$21,COLUMNS($A4:B4),FALSE) -> Banco Unión | C4: =+HLOOKUP($A4,'Obligaciones financieras'!$Q$1:$HV$21,COLUMNS($A4:C4),FALSE) -> BUN | D4: =+HLOOKUP($A4,'Obligaciones financieras'!$Q$1:$HV$21,COLUMNS($A4:D4),FALSE) -> Bolivanos | E4: =+HLOOKUP($A4,'Obligaciones financieras'!$Q$1:$HV$21,COLUMNS($A4:E4),FALSE)*100 -> 6 | F4: =+HLOOKUP($A4,'Obligaciones financieras'!$Q$1:$HV$21,COLUMNS($A4:F4),FALSE) -> Trimestral | H4: =+HLOOKUP($A4,'Obligaciones financieras'!$Q$1:$HV$21,COLUMNS($A4:H4),FALSE) -> 48997 | K4: =+HLOOKUP($A4,'Obligaciones financieras'!$Q$1:$HV$21,COLUMNS($A4:K4),FALSE) -> 51796168 | L4: =+HLOOKUP($A4,'Obligaciones financieras'!$Q$1:$HV$21,COLUMNS($A4:L4),FALSE)*100 -> 30.88359 | M4: =+HLOOKUP($A4,'Obligaciones financieras'!$Q$1:$HV$21,COLUMNS($A4:M4),FALSE) -> 15996516
A5: 1271559 | B5: =+HLOOKUP($A5,'Obligaciones financieras'!$Q$1:$HV$21,COLUMNS($A5:B5),FALSE) -> Banco Bisa | C5: =+HLOOKUP($A5,'Obligaciones financieras'!$Q$1:$HV$21,COLUMNS($A5:C5),FALSE) -> BIS | D5: =+HLOOKUP($A5,'Obligaciones financieras'!$Q$1:$HV$21,COLUMNS($A5:D5),FALSE) -> Bolivanos | E5: =+HLOOKUP($A5,'Obligaciones financieras'!$Q$1:$HV$21,COLUMNS($A5:E5),FALSE)*100 -> 6 | F5: =+HLOOKUP($A5,'Obligaciones financieras'!$Q$1:$HV$21,COLUMNS($A5:F5),FALSE) -> Trimestral | H5: =+HLOOKUP($A5,'Obligaciones financieras'!$Q$1:$HV$21,COLUMNS($A5:H5),FALSE) -> 47107 | K5: =+HLOOKUP($A5,'Obligaciones financieras'!$Q$1:$HV$21,COLUMNS($A5:K5),FALSE) -> 53476614 | L5: =+HLOOKUP($A5,'Obligaciones financieras'!$Q$1:$HV$21,COLUMNS($A5:L5),FALSE)*100 -> 100 | M5: =+HLOOKUP($A5,'Obligaciones financieras'!$Q$1:$HV$21,COLUMNS($A5:M5),FALSE) -> 53476614
A6: 1358960 | B6: =+HLOOKUP($A6,'Obligaciones financieras'!$Q$1:$HV$21,COLUMNS($A6:B6),FALSE) -> Banco Bisa | C6: =+HLOOKUP($A6,'Obligaciones financieras'!$Q$1:$HV$21,COLUMNS($A6:C6),FALSE) -> BIS | D6: =+HLOOKUP($A6,'Obligaciones financieras'!$Q$1:$HV$21,COLUMNS($A6:D6),FALSE) -> Bolivanos | E6: =+HLOOKUP($A6,'Obligaciones financieras'!$Q$1:$HV$21,COLUMNS($A6:E6),FALSE)*100 -> 6 | F6: =+HLOOKUP($A6,'Obligaciones financieras'!$Q$1:$HV$21,COLUMNS($A6:F6),FALSE) -> Trimestral | H6: =+HLOOKUP($A6,'Obligaciones financieras'!$Q$1:$HV$21,COLUMNS($A6:H6),FALSE) -> 47398 | K6: =+HLOOKUP($A6,'Obligaciones financieras'!$Q$1:$HV$21,COLUMNS($A6:K6),FALSE) -> 4571867.8 | L6: =+HLOOKUP($A6,'Obligaciones financieras'!$Q$1:$HV$21,COLUMNS($A6:L6),FALSE)*100 -> 22.702943 | M6: =+HLOOKUP($A6,'Obligaciones financieras'!$Q$1:$HV$21,COLUMNS($A6:M6),FALSE) -> 1037948.5
A7: 1295150 | B7: =+HLOOKUP($A7,'Obligaciones financieras'!$Q$1:$HV$21,COLUMNS($A7:B7),FALSE) -> Banco Bisa | C7: =+HLOOKUP($A7,'Obligaciones financieras'!$Q$1:$HV$21,COLUMNS($A7:C7),FALSE) -> BIS | D7: =+HLOOKUP($A7,'Obligaciones financieras'!$Q$1:$HV$21,COLUMNS($A7:D7),FALSE) -> Bolivanos | E7: =+HLOOKUP($A7,'Obligaciones financieras'!$Q$1:$HV$21,COLUMNS($A7:E7),FALSE)*100 -> 6 | F7: =+HLOOKUP($A7,'Obligaciones financieras'!$Q$1:$HV$21,COLUMNS($A7:F7),FALSE) -> Trimestral | H7: =+HLOOKUP($A7,'Obligaciones financieras'!$Q$1:$HV$21,COLUMNS($A7:H7),FALSE) -> 47375 | K7: =+HLOOKUP($A7,'Obligaciones financieras'!$Q$1:$HV$21,COLUMNS($A7:K7),FALSE) -> 1669085.9 | L7: =+HLOOKUP($A7,'Obligaciones financieras'!$Q$1:$HV$21,COLUMNS($A7:L7),FALSE)*100 -> 100 | M7: =+HLOOKUP($A7,'Obligaciones financieras'!$Q$1:$HV$21,COLUMNS($A7:M7),FALSE) -> 1669085.9
A8: 101243178 | B8: =+HLOOKUP($A8,'Obligaciones financieras'!$Q$1:$HV$21,COLUMNS($A8:B8),FALSE) -> Banco Ganadero | C8: =+HLOOKUP($A8,'Obligaciones financieras'!$Q$1:$HV$21,COLUMNS($A8:C8),FALSE) -> GAN | D8: =+HLOOKUP($A8,'Obligaciones financieras'!$Q$1:$HV$21,COLUMNS($A8:D8),FALSE) -> Bolivanos | E8: =+HLOOKUP($A8,'Obligaciones financieras'!$Q$1:$HV$21,COLUMNS($A8:E8),FALSE)*100 -> 6 | F8: =+HLOOKUP($A8,'Obligaciones financieras'!$Q$1:$HV$21,COLUMNS($A8:F8),FALSE) -> Mensual | H8: =+HLOOKUP($A8,'Obligaciones financieras'!$Q$1:$HV$21,COLUMNS($A8:H8),FALSE) -> 46609 | K8: =+HLOOKUP($A8,'Obligaciones financieras'!$Q$1:$HV$21,COLUMNS($A8:K8),FALSE) -> 29810000 | L8: =+HLOOKUP($A8,'Obligaciones financieras'!$Q$1:$HV$21,COLUMNS($A8:L8),FALSE)*100 -> 86.082018 | M8: =+HLOOKUP($A8,'Obligaciones financieras'!$Q$1:$HV$21,COLUMNS($A8:M8),FALSE) -> 25661049
A9: 315101121500077 | B9: =+HLOOKUP($A9,'Obligaciones financieras'!$Q$1:$HV$21,COLUMNS($A9:B9),FALSE) -> Banco de Desarrollo Productivo | C9: =+HLOOKUP($A9,'Obligaciones financieras'!$Q$1:$HV$21,COLUMNS($A9:C9),FALSE) -> BDP | D9: =+HLOOKUP($A9,'Obligaciones financieras'!$Q$1:$HV$21,COLUMNS($A9:D9),FALSE) -> Bolivanos | E9: =+HLOOKUP($A9,'Obligaciones financieras'!$Q$1:$HV$21,COLUMNS($A9:E9),FALSE)*100 -> 5.8 | F9: =+HLOOKUP($A9,'Obligaciones financieras'!$Q$1:$HV$21,COLUMNS($A9:F9),FALSE) -> Trimestral | H9: =+HLOOKUP($A9,'Obligaciones financieras'!$Q$1:$HV$21,COLUMNS($A9:H9),FALSE) -> 49111 | K9: =+HLOOKUP($A9,'Obligaciones financieras'!$Q$1:$HV$21,COLUMNS($A9:K9),FALSE) -> 9174681.5 | L9: =+HLOOKUP($A9,'Obligaciones financieras'!$Q$1:$HV$21,COLUMNS($A9:L9),FALSE)*100 -> 99.370812 | M9: =+HLOOKUP($A9,'Obligaciones financieras'!$Q$1:$HV$21,COLUMNS($A9:M9),FALSE) -> 9116955.5
A10: 315101121500078f | B10: =+HLOOKUP($A10,'Obligaciones financieras'!$Q$1:$HV$21,COLUMNS($A10:B10),FALSE) -> Banco de Desarrollo Productivo | C10: =+HLOOKUP($A10,'Obligaciones financieras'!$Q$1:$HV$21,COLUMNS($A10:C10),FALSE) -> BDP | D10: =+HLOOKUP($A10,'Obligaciones financieras'!$Q$1:$HV$21,COLUMNS($A10:D10),FALSE) -> Bolivanos | E10: =+HLOOKUP($A10,'Obligaciones financieras'!$Q$1:$HV$21,COLUMNS($A10:E10),FALSE)*100 -> 5.82 | F10: =+HLOOKUP($A10,'Obligaciones financieras'!$Q$1:$HV$21,COLUMNS($A10:F10),FALSE) -> Trimestral | H10: =+HLOOKUP($A10,'Obligaciones financieras'!$Q$1:$HV$21,COLUMNS($A10:H10),FALSE) -> 48765 | K10: =+HLOOKUP($A10,'Obligaciones financieras'!$Q$1:$HV$21,COLUMNS($A10:K10),FALSE) -> 8467855 | L10: =+HLOOKUP($A10,'Obligaciones financieras'!$Q$1:$HV$21,COLUMNS($A10:L10),FALSE)*100 -> 13.104947 | M10: =+HLOOKUP($A10,'Obligaciones financieras'!$Q$1:$HV$21,COLUMNS($A10:M10),FALSE) -> 1109707.9
A11: 315101121500021 | B11: =+HLOOKUP($A11,'Obligaciones financieras'!$Q$1:$HV$21,COLUMNS($A11:B11),FALSE) -> Banco de Desarrollo Productivo | C11: =+HLOOKUP($A11,'Obligaciones financieras'!$Q$1:$HV$21,COLUMNS($A11:C11),FALSE) -> BDP | D11: =+HLOOKUP($A11,'Obligaciones financieras'!$Q$1:$HV$21,COLUMNS($A11:D11),FALSE) -> Bolivanos | E11: =+HLOOKUP($A11,'Obligaciones financieras'!$Q$1:$HV$21,COLUMNS($A11:E11),FALSE)*100 -> 5.99 | F11: =+HLOOKUP($A11,'Obligaciones financieras'!$Q$1:$HV$21,COLUMNS($A11:F11),FALSE) -> Trimestral | H11: =+HLOOKUP($A11,'Obligaciones financieras'!$Q$1:$HV$21,COLUMNS($A11:H11),FALSE) -> 49111 | K11: =+HLOOKUP($A11,'Obligaciones financieras'!$Q$1:$HV$21,COLUMNS($A11:K11),FALSE) -> 2794681.5 | L11: =+HLOOKUP($A11,'Obligaciones financieras'!$Q$1:$HV$21,COLUMNS($A11:L11),FALSE)*100 -> 100 | M11: =+HLOOKUP($A11,'Obligaciones financieras'!$Q$1:$HV$21,COLUMNS($A11:M11),FALSE) -> 2794681.5
A12: 2010014418 | B12: =+HLOOKUP($A12,'Obligaciones financieras'!$Q$1:$HV$21,COLUMNS($A12:B12),FALSE) -> BNB leasing | C12: =+HLOOKUP($A12,'Obligaciones financieras'!$Q$1:$HV$21,COLUMNS($A12:C12),FALSE) -> BNL | D12: =+HLOOKUP($A12,'Obligaciones financieras'!$Q$1:$HV$21,COLUMNS($A12:D12),FALSE) -> Bolivanos | E12: =+HLOOKUP($A12,'Obligaciones financieras'!$Q$1:$HV$21,COLUMNS($A12:E12),FALSE)*100 -> 6 | F12: =+HLOOKUP($A12,'Obligaciones financieras'!$Q$1:$HV$21,COLUMNS($A12:F12),FALSE) -> Trimestral | H12: =+HLOOKUP($A12,'Obligaciones financieras'!$Q$1:$HV$21,COLUMNS($A12:H12),FALSE) -> 46552 | K12: =+HLOOKUP($A12,'Obligaciones financieras'!$Q$1:$HV$21,COLUMNS($A12:K12),FALSE) -> 309433.84 | L12: =+HLOOKUP($A12,'Obligaciones financieras'!$Q$1:$HV$21,COLUMNS($A12:L12),FALSE)*100 -> 100 | M12: =+HLOOKUP($A12,'Obligaciones financieras'!$Q$1:$HV$21,COLUMNS($A12:M12),FALSE) -> 309433.84
A13: 2010014118 | B13: =+HLOOKUP($A13,'Obligaciones financieras'!$Q$1:$HV$21,COLUMNS($A13:B13),FALSE) -> BNB leasing | C13: =+HLOOKUP($A13,'Obligaciones financieras'!$Q$1:$HV$21,COLUMNS($A13:C13),FALSE) -> BNL | D13: =+HLOOKUP($A13,'Obligaciones financieras'!$Q$1:$HV$21,COLUMNS($A13:D13),FALSE) -> Bolivanos | E13: =+HLOOKUP($A13,'Obligaciones financieras'!$Q$1:$HV$21,COLUMNS($A13:E13),FALSE)*100 -> 6 | F13: =+HLOOKUP($A13,'Obligaciones financieras'!$Q$1:$HV$21,COLUMNS($A13:F13),FALSE) -> Trimestral | H13: =+HLOOKUP($A13,'Obligaciones financieras'!$Q$1:$HV$21,COLUMNS($A13:H13),FALSE) -> 46552 | K13: =+HLOOKUP($A13,'Obligaciones financieras'!$Q$1:$HV$21,COLUMNS($A13:K13),FALSE) -> 309433.84 | L13: =+HLOOKUP($A13,'Obligaciones financieras'!$Q$1:$HV$21,COLUMNS($A13:L13),FALSE)*100 -> 100 | M13: =+HLOOKUP($A13,'Obligaciones financieras'!$Q$1:$HV$21,COLUMNS($A13:M13),FALSE) -> 309433.84
A14: 2010013918 | B14: =+HLOOKUP($A14,'Obligaciones financieras'!$Q$1:$HV$21,COLUMNS($A14:B14),FALSE) -> BNB leasing | C14: =+HLOOKUP($A14,'Obligaciones financieras'!$Q$1:$HV$21,COLUMNS($A14:C14),FALSE) -> BNL | D14: =+HLOOKUP($A14,'Obligaciones financieras'!$Q$1:$HV$21,COLUMNS($A14:D14),FALSE) -> Bolivanos | E14: =+HLOOKUP($A14,'Obligaciones financieras'!$Q$1:$HV$21,COLUMNS($A14:E14),FALSE)*100 -> 6 | F14: =+HLOOKUP($A14,'Obligaciones financieras'!$Q$1:$HV$21,COLUMNS($A14:F14),FALSE) -> Trimestral | H14: =+HLOOKUP($A14,'Obligaciones financieras'!$Q$1:$HV$21,COLUMNS($A14:H14),FALSE) -> 46552 | K14: =+HLOOKUP($A14,'Obligaciones financieras'!$Q$1:$HV$21,COLUMNS($A14:K14),FALSE) -> 309433.84 | L14: =+HLOOKUP($A14,'Obligaciones financieras'!$Q$1:$HV$21,COLUMNS($A14:L14),FALSE)*100 -> 100 | M14: =+HLOOKUP($A14,'Obligaciones financieras'!$Q$1:$HV$21,COLUMNS($A14:M14),FALSE) -> 309433.84
A15: 2010014218 | B15: =+HLOOKUP($A15,'Obligaciones financieras'!$Q$1:$HV$21,COLUMNS($A15:B15),FALSE) -> BNB leasing | C15: =+HLOOKUP($A15,'Obligaciones financieras'!$Q$1:$HV$21,COLUMNS($A15:C15),FALSE) -> BNL | D15: =+HLOOKUP($A15,'Obligaciones financieras'!$Q$1:$HV$21,COLUMNS($A15:D15),FALSE) -> Bolivanos | E15: =+HLOOKUP($A15,'Obligaciones financieras'!$Q$1:$HV$21,COLUMNS($A15:E15),FALSE)*100 -> 6 | F15: =+HLOOKUP($A15,'Obligaciones financieras'!$Q$1:$HV$21,COLUMNS($A15:F15),FALSE) -> Trimestral | H15: =+HLOOKUP($A15,'Obligaciones financieras'!$Q$1:$HV$21,COLUMNS($A15:H15),FALSE) -> 46552 | K15: =+HLOOKUP($A15,'Obligaciones financieras'!$Q$1:$HV$21,COLUMNS($A15:K15),FALSE) -> 309433.84 | L15: =+HLOOKUP($A15,'Obligaciones financieras'!$Q$1:$HV$21,COLUMNS($A15:L15),FALSE)*100 -> 100 | M15: =+HLOOKUP($A15,'Obligaciones financieras'!$Q$1:$HV$21,COLUMNS($A15:M15),FALSE) -> 309433.84
A16: 2010014318 | B16: =+HLOOKUP($A16,'Obligaciones financieras'!$Q$1:$HV$21,COLUMNS($A16:B16),FALSE) -> BNB leasing | C16: =+HLOOKUP($A16,'Obligaciones financieras'!$Q$1:$HV$21,COLUMNS($A16:C16),FALSE) -> BNL | D16: =+HLOOKUP($A16,'Obligaciones financieras'!$Q$1:$HV$21,COLUMNS($A16:D16),FALSE) -> Bolivanos | E16: =+HLOOKUP($A16,'Obligaciones financieras'!$Q$1:$HV$21,COLUMNS($A16:E16),FALSE)*100 -> 6 | F16: =+HLOOKUP($A16,'Obligaciones financieras'!$Q$1:$HV$21,COLUMNS($A16:F16),FALSE) -> Trimestral | H16: =+HLOOKUP($A16,'Obligaciones financieras'!$Q$1:$HV$21,COLUMNS($A16:H16),FALSE) -> 46714 | K16: =+HLOOKUP($A16,'Obligaciones financieras'!$Q$1:$HV$21,COLUMNS($A16:K16),FALSE) -> 388403.55 | L16: =+HLOOKUP($A16,'Obligaciones financieras'!$Q$1:$HV$21,COLUMNS($A16:L16),FALSE)*100 -> 100 | M16: =+HLOOKUP($A16,'Obligaciones financieras'!$Q$1:$HV$21,COLUMNS($A16:M16),FALSE) -> 388403.55
A17: 2010014018 | B17: =+HLOOKUP($A17,'Obligaciones financieras'!$Q$1:$HV$21,COLUMNS($A17:B17),FALSE) -> BNB leasing | C17: =+HLOOKUP($A17,'Obligaciones financieras'!$Q$1:$HV$21,COLUMNS($A17:C17),FALSE) -> BNL | D17: =+HLOOKUP($A17,'Obligaciones financieras'!$Q$1:$HV$21,COLUMNS($A17:D17),FALSE) -> Bolivanos | E17: =+HLOOKUP($A17,'Obligaciones financieras'!$Q$1:$HV$21,COLUMNS($A17:E17),FALSE)*100 -> 6 | F17: =+HLOOKUP($A17,'Obligaciones financieras'!$Q$1:$HV$21,COLUMNS($A17:F17),FALSE) -> Trimestral | H17: =+HLOOKUP($A17,'Obligaciones financieras'!$Q$1:$HV$21,COLUMNS($A17:H17),FALSE) -> 46714 | K17: =+HLOOKUP($A17,'Obligaciones financieras'!$Q$1:$HV$21,COLUMNS($A17:K17),FALSE) -> 388403.55 | L17: =+HLOOKUP($A17,'Obligaciones financieras'!$Q$1:$HV$21,COLUMNS($A17:L17),FALSE)*100 -> 100 | M17: =+HLOOKUP($A17,'Obligaciones financieras'!$Q$1:$HV$21,COLUMNS($A17:M17),FALSE) -> 388403.55

Sheet info
A1: Nro de la operación | B1: Entidad | C1: Cod. Entidad | D1: Moneda | E1: Tasa | F1: Periodicidad | G1: vencimiento | H1: Saldo a capital | I1: % adeudado por Cemento | J1: Saldo a capital Cemento
A2: 3167401 | B2: Fideicomiso - Banco Unión | C2: FID - BUN | D2: Bolivanos | E2: 6 | F2: Trimestral | G2: 48248 | H2: 2.3034329e+08 | I2: 57.390185 | J2: 1.3219444e+08
A3: 2767412 | B3: Banco Unión | C3: BUN | D3: Bolivanos | E3: 5.5 | F3: Trimestral | G3: 48058 | H3: 1241907.9 | I3: 100 | J3: 1241907.9
A4: 2764418 | B4: Banco Unión | C4: BUN | D4: Bolivanos | E4: 6 | F4: Trimestral | G4: 48997 | H4: 51796168 | I4: 30.88359 | J4: 15996516
A5: 1271559 | B5: Banco Bisa | C5: BIS | D5: Bolivanos | E5: 6 | F5: Trimestral | G5: 47107 | H5: 53476614 | I5: 100 | J5: 53476614
A6: 1358960 | B6: Banco Bisa | C6: BIS | D6: Bolivanos | E6: 6 | F6: Trimestral | G6: 47398 | H6: 4571867.8 | I6: 22.702943 | J6: 1037948.5
A7: 1295150 | B7: Banco Bisa | C7: BIS | D7: Bolivanos | E7: 6 | F7: Trimestral | G7: 47375 | H7: 1669085.9 | I7: 100 | J7: 1669085.9
A8: 101243178 | B8: Banco Ganadero | C8: GAN | D8: Bolivanos | E8: 6 | F8: Mensual | G8: 46609 | H8: 29810000 | I8: 86.082018 | J8: 25661049
A9: 315101121500077 | B9: Banco de Desarrollo Productivo | C9: BDP | D9: Bolivanos | E9: 5.8 | F9: Trimestral | G9: 49111 | H9: 9174681.5 | I9: 99.370812 | J9: 9116955.5
A10: 315101121500078f | B10: Banco de Desarrollo Productivo | C10: BDP | D10: Bolivanos | E10: 5.82 | F10: Trimestral | G10: 48765 | H10: 8467855 | I10: 13.104947 | J10: 1109707.9
A11: 315101121500021 | B11: Banco de Desarrollo Productivo | C11: BDP | D11: Bolivanos | E11: 5.99 | F11: Trimestral | G11: 49111 | H11: 2794681.5 | I11: 100 | J11: 2794681.5
A12: 2010014418 | B12: BNB leasing | C12: BNL | D12: Bolivanos | E12: 6 | F12: Trimestral | G12: 46552 | H12: 309433.84 | I12: 100 | J12: 309433.84
A13: 2010014118 | B13: BNB leasing | C13: BNL | D13: Bolivanos | E13: 6 | F13: Trimestral | G13: 46552 | H13: 309433.84 | I13: 100 | J13: 309433.84
A14: 2010013918 | B14: BNB leasing | C14: BNL | D14: Bolivanos | E14: 6 | F14: Trimestral | G14: 46552 | H14: 309433.84 | I14: 100 | J14: 309433.84
A15: 2010014218 | B15: BNB leasing | C15: BNL | D15: Bolivanos | E15: 6 | F15: Trimestral | G15: 46552 | H15: 309433.84 | I15: 100 | J15: 309433.84
A16: 2010014318 | B16: BNB leasing | C16: BNL | D16: Bolivanos | E16: 6 | F16: Trimestral | G16: 46714 | H16: 388403.55 | I16: 100 | J16: 388403.55
A17: 2010014018 | B17: BNB leasing | C17: BNL | D17: Bolivanos | E17: 6 | F17: Trimestral | G17: 46714 | H17: 388403.55 | I17: 100 | J17: 388403.55

Sheet 3167401
A1: Fecha | B1: Saldo adeudado | C1: Amortización | D1: Intereses corrientes | E1: Intereses diferidos | F1: Total Cuota
A2: 45506 | B2: 1.3235192e+08 | C2: 0 | D2: 0 | E2: 0 | F2: 0
A3: 45611 | B3: 1.3231255e+08 | C3: 39369.667 | D3: 2316158.6 | E3: 471550.55 | F3: 2827078.8
A4: 45703 | B4: 1.3227318e+08 | C4: 39369.667 | D4: 2028792.4 | E4: 471550.55 | F4: 2539712.7
A5: 45792 | B5: 1.3223381e+08 | C5: 39369.667 | D5: 1962052.2 | E5: 471550.55 | F5: 2472972.4
A6: 45884 | B6: 1.3219444e+08 | C6: 39369.667 | D6: 2027585.1 | E6: 471550.55 | F6: 2538505.3
A7: 45976 | B7: 1.0182495e+08 | C7: 30369494 | D7: 2026981.4 | E7: 471550.55 | F7: 32868026
A8: 46068 | B8: 97751949 | C8: 4072997.9 | D8: 1561315.9 | E8: 471550.55 | F8: 6105864.3
A9: 46157 | B9: 93678951 | C9: 4072997.9 | D9: 1449987.2 | E9: 471550.55 | F9: 5994535.7
A10: 46249 | B10: 89605953 | C10: 4072997.9 | D10: 1436410.6 | E10: 471550.55 | F10: 5980959
A11: 46341 | B11: 85532956 | C11: 4072997.9 | D11: 1373958 | E11: 471550.55 | F11: 5918506.4
A12: 46433 | B12: 81459958 | C12: 4072997.9 | D12: 1311505.3 | E12: 471550.55 | F12: 5856053.7
A13: 46522 | B13: 77386960 | C13: 4072997.9 | D13: 1208322.7 | E13: 471550.55 | F13: 5752871.1
... A22: 47345 | B22: 40729979 | C22: 4072997.9 | D22: 686978.98 | E22: 471550.55 | F22: 5231527.4
A23: 47437 | B23: 36656981 | C23: 4072997.9 | D23: 624526.34 | F23: 4697524.2
A24: 47529 | B24: 32583983 | C24: 4072997.9 | D24: 562073.71 | F24: 4635071.6
A25: 47618 | B25: 28510985 | C25: 4072997.9 | D25: 483329.08 | F25: 4556327
A26: 47710 | B26: 24437987 | C26: 4072997.9 | D26: 437168.44 | F26: 4510166.3
A27: 47802 | B27: 20364989 | C27: 4072997.9 | D27: 374715.81 | F27: 4447713.7
A28: 47894 | B28: 16291992 | C28: 4072997.9 | D28: 312263.17 | F28: 4385261.1
A29: 47983 | B29: 12218994 | C29: 4072997.9 | D29: 241664.54 | F29: 4314662.4
A30: 48075 | B30: 8145995.8 | C30: 4072997.9 | D30: 187357.9 | F30: 4260355.8
A31: 48167 | B31: 4072997.9 | C31: 4072997.9 | D31: 124905.27 | F31: 4197903.1
A32: 48248 | B32: 5.5879354e-08 | C32: 4072997.9 | D32: 54985.471 | F32: 4127983.4

Sheet 2767412
A1: Fecha | B1: Saldo adeudado | C1: Amortización | D1: Intereses corrientes | E1: Total Cuota
A2: 45712 | B2: 1345589.5 | C2: 0 | D2: 0 | E2: 0
A3: 45779 | B3: 1293748.7 | C3: 51840.79 | D3: 13773.604 | E3: 65614.394
A4: 45871 | B4: 1241907.9 | C4: 51840.79 | D4: 18184.357 | E4: 70025.147
A5: 45963 | B5: 1190067.1 | C5: 51840.79 | D5: 17455.706 | E5: 69296.496
A6: 46055 | B6: 1138226.3 | C6: 51840.79 | D6: 16727.055 | E6: 68567.845
A7: 46144 | B7: 1086385.6 | C7: 51840.79 | D7: 15476.717 | E7: 67317.507
A8: 46236 | B8: 1034544.8 | C8: 51840.79 | D8: 15269.753 | E8: 67110.543
A9: 46328 | B9: 982703.98 | C9: 51840.79 | D9: 14541.101 | E9: 66381.891
A10: 46420 | B10: 930863.19 | C10: 51840.79 | D10: 13812.45 | E10: 65653.24
A11: 46509 | B11: 879022.4 | C11: 51840.79 | D11: 12657.154 | E11: 64497.944
A12: 46601 | B12: 827181.61 | C12: 51840.79 | D12: 12355.148 | E12: 64195.938
A13: 46693 | B13: 775340.82 | C13: 51840.79 | D13: 11626.497 | E13: 63467.287
... A28: 48058 | B28: -4.802132e-10 | C28: 49569.76 | D28: 666.43788 | E28: 50236.198

Sheet 2764418
A1: Fecha | B1: Saldo adeudado | C1: Amortización | D1: Intereses corrientes | E1: Total Cuota
A2: 45656 | B2: 15996516 | C2: 0 | D2: 0 | E2: 0
A3: 45708 | B3: 15996516 | C3: 0 | D3: 138636.47 | E3: 138636.47
A4: 45797 | B4: 15996516 | C4: 0 | D4: 237281.65 | E4: 237281.65
A5: 45889 | B5: 15996516 | C5: 0 | D5: 245279.91 | E5: 245279.91
A6: 45981 | B6: 15996516 | C6: 0 | D6: 245279.91 | E6: 245279.91
A7: 46073 | B7: 15996516 | C7: 0 | D7: 245279.91 | E7: 245279.91
A8: 46162 | B8: 15996516 | C8: 0 | D8: 237281.65 | E8: 237281.65
A9: 46254 | B9: 15471469 | C9: 525047.46 | D9: 245279.91 | E9: 770327.38
A10: 46346 | B10: 14946421 | C10: 525047.46 | D10: 237229.19 | E10: 762276.65
A11: 46438 | B11: 14421374 | C11: 525047.46 | D11: 229178.46 | E11: 754225.92
A12: 46527 | B12: 13896326 | C12: 525047.46 | D12: 213917.04 | E12: 738964.51
A13: 46619 | B13: 13371279 | C13: 525047.46 | D13: 213077 | E13: 738124.47
... A39: 48997 | B39: -7.4214768e-09 | C39: 245092.12 | D39: 3839.7766 | E39: 248931.9

Sheet 1271559
A1: Fecha | B1: Saldo adeudado | C1: Amortización | D1: Intereses corrientes | E1: Interes prorroga y gracia | F1: Total Cuota
A2: 45736 | B2: 53476614 | C2: 0 | D2: 0 | E2: 0 | F2: 0
A3: 45828 | B3: 53476614 | C3: 0 | D3: 819974.75 | E3: 82616.23 | F3: 902590.98
A4: 45920 | B4: =B3-C4 -> 39476614 | C4: 14000000 | D4: 819974.75 | E4: 82616.23 | F4: 902590.98
A5: 46011 | B5: =B4-C5 -> 39476614 | D5: 355289.53 | E5: 82616.23 | F5: =SUM(C5:E5) -> 437905.76
A6: 46101 | B6: =B5-C6 -> 39476614 | C6: 0 | D6: 592149.21 | E6: 82616.23 | F6: =SUM(C6:E6) -> 674765.44
A7: 46193 | B7: =B6-C7 -> 39476614 | C7: 0 | D7: 605308.08 | E7: 82616.23 | F7: =SUM(C7:E7) -> 687924.31
A8: 46285 | B8: =B7-C8 -> 39476614 | D8: 605308.08 | E8: 82616.23 | F8: =SUM(C8:E8) -> 687924.31
A9: 46376 | B9: =B8-C9 -> 39476614 | D9: 598728.65 | E9: 82616.23 | F9: =SUM(C9:E9) -> 681344.88
A10: 46466 | B10: =B9-C10 -> 37433630 | C10: 2042984.2 | D10: 592149.21 | E10: 82616.23 | F10: =SUM(C10:E10) -> 2717749.7
A11: 46558 | B11: =B10-C11 -> 32085968 | C11: 5347661.4 | D11: 573982.32 | E11: 82616.23 | F11: =SUM(C11:E11) -> 6004260
A12: 46650 | B12: =B11-C12 -> 26738307 | C12: 5347661.4 | D12: 491984.85 | E12: 82616.23 | F12: =SUM(C12:E12) -> 5922262.5
A13: 46741 | B13: =B12-C13 -> 21390646 | C13: 5347661.4 | D13: 405530.99 | E13: 82616.23 | F13: =SUM(C13:E13) -> 5835808.6
A14: 46832 | B14: =B13-C14 -> 16042984 | C14: 5347661.4 | D14: 324424.79 | E14: 82616.23 | F14: =SUM(C14:E14) -> 5754702.4
A15: 46924 | B15: =B14-C15 -> 10695323 | C15: 5347661.4 | D15: 245992.43 | E15: 82616.23 | F15: =SUM(C15:E15) -> 5676270.1
A16: 47016 | B16: =B15-C16 -> 5347661.4 | C16: 5347661.4 | D16: 163994.95 | E16: 82616.23 | F16: =SUM(C16:E16) -> 5594272.6
A17: 47107 | B17: =B16-C17 -> 7.4505806e-09 | C17: 5347661.4 | D17: 81106.2 | E17: 82616.23 | F17: =SUM(C17:E17) -> 5511383.8

Sheet 1358960
A1: Fecha | B1: Saldo adeudado | C1: Amortización | D1: Amortización cap diferido | E1: Intereses corrientes | F1: Intereses prorroga gracia | G1: Total Cuota
A2: 45677 | B2: 1154729.4
A3: 45702 | B3: 1096992.9 | C3: 57736.47 | D3: 0 | E3: 4811.3725 | F3: 1642.8395 | G3: 64190.682
A4: 45858 | B4: 1039256.4 | C4: 57736.47 | D4: 2821.4285 | E4: 28521.816 | F4: 1642.8395 | G4: 90722.554
A5: 45950 | B5: 981519.98 | C5: 57736.47 | D5: 2821.4285 | E5: 15935.266 | F5: 1642.8395 | G5: 78136.004
A6: 46042 | B6: 923783.51 | C6: 57736.47 | D6: 2821.4285 | E6: 15049.973 | F6: 1642.8395 | G6: 77250.711
A7: 46132 | B7: 866047.04 | C7: 57736.47 | D7: 2821.4285 | E7: 13856.753 | F7: 1642.8395 | G7: 76057.491
A8: 46223 | B8: 808310.57 | C8: 57736.47 | D8: 2821.4285 | E8: 13135.047 | F8: 1642.8395 | G8: 75335.785
A9: 46315 | B9: 750574.1 | C9: 57736.47 | D9: 2821.4285 | E9: 12394.095 | F9: 1642.8395 | G9: 74594.833
A10: 46407 | B10: 692837.63 | C10: 57736.47 | D10: 2821.4285 | E10: 11508.803 | F10: 1642.8395 | G10: 73709.541
A11: 46497 | B11: 635101.16 | C11: 57736.47 | D11: 2821.4285 | E11: 10392.564 | F11: 1642.8395 | G11: 72593.302
A12: 46588 | B12: 577364.69 | C12: 57736.47 | D12: 2821.4285 | E12: 9632.3676 | F12: 1642.8395 | G12: 71833.106
A13: 46680 | B13: 519628.22 | C13: 57736.47 | D13: 2821.4285 | E13: 8852.9252 | F13: 1642.8395 | G13: 71053.663
A14: 46772 | B14: 461891.75 | C14: 57736.47 | D14: 2821.4285 | E14: 7967.6327 | F14: 1642.8395 | G14: 70168.371
... A21: 47398 | B21: 0.0056757364 | C21: 115472.92 | D21: 14107.143 | E21: 1520.3935 | F21: 1642.8395 | G21: 132743.3

Sheet 1295150
A1: Fecha | B1: Saldo adeudado | C1: Amortización | D1: Intereses corrientes | E1: Total Cuota
A2: 45700 | B2: 1669085.9 | C2: 0 | D2: 0 | E2: 0
A3: 45822 | B3: 1669085.9 | C3: 0 | D3: 29209.003 | E3: 29209.003
A4: 45914 | B4: 1669085.9 | C4: 0 | D4: 22393.569 | E4: 22393.569
A5: 46005 | B5: 1564768 | C5: 104317.86 | D5: 22150.161 | E5: 126468.02
A6: 46095 | B6: 1460450.1 | C6: 104317.86 | D6: 20341.984 | E6: 124659.84
A7: 46187 | B7: 1356132.3 | C7: 104317.86 | D7: 19194.488 | E7: 123512.35
A8: 46279 | B8: 1251814.4 | C8: 104317.86 | D8: 17594.947 | E8: 121912.81
A9: 46370 | B9: 1147496.5 | C9: 104317.86 | D9: 15821.544 | E9: 120139.4
A10: 46460 | B10: 1043178.7 | C10: 104317.86 | D10: 14082.913 | E10: 118400.77
A11: 46552 | B11: 938860.83 | C11: 104317.86 | D11: 12796.326 | E11: 117114.19
A12: 46644 | B12: 834542.97 | C12: 104317.86 | D12: 11196.785 | E12: 115514.65
A13: 46735 | B13: 730225.11 | C13: 104317.86 | D13: 9492.9269 | E13: 113810.79
... A20: 47375 | B20: 0 | C20: 104317.85 | D20: 53793.24 | E20: 158111.09

Sheet 101243178
A1: Fecha | B1: Saldo adeudado | C1: Amortización | D1: Intereses corrientes | E1: Total Cuota
A2: 45848 | B2: 26010061
A3: 45879 | B3: 25661049 | C3: 349011.21 | D3: 134385.31 | E3: 483396.52
A4: 45910 | B4: 25312038 | C4: 349011.21 | D4: 132582.09 | E4: 481593.3
A5: 45940 | B5: 24963027 | C5: 349011.21 | D5: 126560.19 | E5: 475571.4
A6: 45971 | B6: 24614016 | C6: 349011.21 | D6: 128975.64 | E6: 477986.85
A7: 46001 | B7: 24265005 | C7: 349011.21 | D7: 123070.08 | E7: 472081.29
A8: 46032 | B8: 23915993 | C8: 349011.21 | D8: 125369.19 | E8: 474380.4
A9: 46063 | B9: 23566982 | C9: 349011.21 | D9: 123565.97 | E9: 472577.18
A10: 46091 | B10: 23217971 | C10: 349011.21 | D10: 109979.25 | E10: 458990.46
A11: 46122 | B11: 22868960 | C11: 349011.21 | D11: 119959.52 | E11: 468970.73
A12: 46152 | B12: 22519949 | C12: 349011.21 | D12: 114344.8 | E12: 463356.01
A13: 46183 | B13: 22170937 | C13: 349011.21 | D13: 116353.07 | E13: 465364.28
A14: 46213 | B14: 20587299 | C14: 1583638.4 | D14: 110854.69 | E14: 1694493.1
... A27: 46609 | B27: 0.068803104 | C27: 1583638.4 | D27: 8182.132 | E27: 1591820.5

Sheet 315101121500077
A1: Fecha | B1: Saldo adeudado | C1: Amortización | D1: Intereses corrientes | E1: Total Cuota
A2: 45721 | B2: 9116955.5
A3: 45838 | B3: 9116955.5 | C3: 0 | D3: 138152.48 | E3: 138152.48
A4: 45925 | B4: 9116955.5 | C4: 0 | D4: 127789.32 | E4: 127789.32
A5: 46017 | B5: 9116955.5 | C5: 0 | D5: 135133.54 | E5: 135133.54
A6: 46107 | B6: 9102050 | C6: 14905.56 | D6: 132195.85 | E6: 147101.41
A7: 46198 | B7: 9087144.4 | C7: 14905.62 | D7: 133446.17 | E7: 148351.79
A8: 46289 | B8: 8803171.1 | C8: 283973.26 | D8: 133227.63 | E8: 417200.89
A9: 46380 | B9: 8519197.8 | C9: 283973.26 | D9: 129064.27 | E9: 413037.53
A10: 46471 | B10: 8235224.6 | C10: 283973.26 | D10: 124900.9 | E10: 408874.16
A11: 46562 | B11: 7951251.3 | C11: 283973.26 | D11: 120737.54 | E11: 404710.8
A12: 46653 | B12: 7667278.1 | C12: 283973.26 | D12: 116574.18 | E12: 400547.44
A13: 46744 | B13: 7383304.8 | C13: 283973.26 | D13: 112410.82 | E13: 396384.08
A14: 46835 | B14: 7099331.5 | C14: 283973.26 | D14: 108247.45 | E14: 392220.71
... A39: 49111 | B39: 0.038867459 | C39: 283973.26 | D39: 4209.12 | E39: 288182.38

Sheet 315101121500078f
A1: Fecha | B1: Saldo adeudado | C1: Amortización | D1: Intereses corrientes | E1: Total Cuota
A2: 45721 | B2: 1109707.9
A3: 45838 | B3: 1109707.9 | C3: 0 | D3: 16421.12 | E3: 16421.12
A4: 45936 | B4: 1109707.9 | C4: 0 | D4: 17581.472 | E4: 17581.472
A5: 46027 | B5: 1109707.9 | C5: 0 | D5: 16325.652 | E5: 16325.652
A6: 46118 | B6: 1107774.2 | C6: 1933.63 | D6: 16325.652 | E6: 18259.282
A7: 46209 | B7: 1105840.6 | C7: 1933.65 | D7: 16297.205 | E7: 18230.855
A8: 46300 | B8: 1066346.3 | C8: 39494.31 | D8: 16268.758 | E8: 55763.068
A9: 46392 | B9: 1026852 | C9: 39494.31 | D9: 15860.124 | E9: 55354.434
A10: 46482 | B10: 987357.66 | C10: 39494.31 | D10: 14940.696 | E10: 54435.006
A11: 46573 | B11: 947863.35 | C11: 39494.31 | D11: 14525.677 | E11: 54019.987
A12: 46665 | B12: 908369.04 | C12: 39494.31 | D12: 14097.888 | E12: 53592.198
A13: 46757 | B13: 868874.73 | C13: 39494.31 | D13: 13510.476 | E13: 53004.786
A14: 46848 | B14: 829380.42 | C14: 39494.31 | D14: 12782.595 | E14: 52276.905
... A35: 48765 | B35: -0.087313402 | C35: 39494.31 | D35: 581.02584 | E35: 40075.336

Sheet 315101121500021
A1: Fecha | B1: Saldo adeudado | C1: Amortización | D1: Intereses corrientes | E1: Total Cuota
A2: 45657 | B2: 2794681.5
A3: 45721 | B3: 2794681.5 | C3: 0 | D3: 17114.156 | E3: 17200.556
A4: 45838 | B4: 2794681.5 | C4: 0 | D4: 38370.47 | E4: 58214.95
A5: 45925 | B5: 2794681.5 | C5: 0 | D5: 17027.76 | E5: 17027.76
A6: 46017 | B6: 2794681.5 | C6: 0 | D6: 18006.37 | E6: 18006.37
A7: 46107 | B7: 2789681.5 | C7: 5000.03 | D7: 18235.06 | E7: 23235.09
A8: 46198 | B8: 2784681.5 | C8: 5000 | D8: 18355.08 | E8: 23355.08
A9: 46289 | B9: 2744464.6 | C9: 40216.85 | D9: 18279.37 | E9: 58496.22
A10: 46380 | B10: 2704247.8 | C10: 40216.85 | D10: 17670.43 | E10: 57887.28
A11: 46471 | B11: 2664030.9 | C11: 40216.85 | D11: 17061.49 | E11: 57278.34
A12: 46562 | B12: 2623814.1 | C12: 40216.85 | D12: 16452.55 | E12: 56669.4
A13: 46653 | B13: 2583597.2 | C13: 40216.85 | D13: 15843.61 | E13: 56060.46
A14: 46744 | B14: 2543380.4 | C14: 40216.85 | D14: 15234.68 | E14: 55451.53
... A40: 49111 | B40: -2.5611371e-09 | C40: 548258.31 | D40: 79526.41 | E40: 627784.72

Sheet 2010014418
A1: Fecha | B1: Saldo adeudado | C1: Amortización | D1: Intereses corrientes | E1: Total Cuota
A2: 45742 | B2: 346343.01
A3: 45832 | B3: 309433.84 | C3: 36909.17 | D3: 4285.87 | E3: 41195.04
A4: 45922 | B4: 271740.35 | C4: 37693.49 | D4: 3732.23 | E4: 41425.72
A5: 46012 | B5: 233245.87 | C5: 38494.48 | D5: 3166.83 | E5: 41661.31
A6: 46102 | B6: 193933.38 | C6: 39312.49 | D6: 2589.41 | E6: 41901.9
A7: 46192 | B7: 153785.5 | C7: 40147.88 | D7: 1999.73 | E7: 42147.61
A8: 46282 | B8: 112784.48 | C8: 41001.02 | D8: 1397.51 | E8: 42398.53
A9: 46372 | B9: 70912.104 | C9: 41872.38 | D9: 782.49 | E9: 42654.87
A10: 46462 | B10: 41229.074 | C10: 29683.03 | D10: 17605.8 | E10: 47288.83
A11: 46552 | B11: 10293.844 | C11: 30935.23 | D11: 14697.99 | E11: 45633.22
A12: 46552 | B12: 0.0040000001 | C12: 10293.84 | D12: 0 | E12: 10293.84

Sheet 2010014118
A1: Fecha | B1: Saldo adeudado | C1: Amortización | D1: Intereses corrientes | E1: Total Cuota
A2: 45742 | B2: 346343.01
A3: 45832 | B3: 309433.84 | C3: 36909.17 | D3: 4285.87 | E3: 41195.04
A4: 45922 | B4: 271740.35 | C4: 37693.49 | D4: 3732.23 | E4: 41425.72
A5: 46012 | B5: 233245.87 | C5: 38494.48 | D5: 3166.83 | E5: 41661.31
A6: 46102 | B6: 193933.38 | C6: 39312.49 | D6: 2589.41 | E6: 41901.9
A7: 46192 | B7: 153785.5 | C7: 40147.88 | D7: 1999.73 | E7: 42147.61
A8: 46282 | B8: 112784.48 | C8: 41001.02 | D8: 1397.51 | E8: 42398.53
A9: 46372 | B9: 70912.104 | C9: 41872.38 | D9: 782.49 | E9: 42654.87
A10: 46462 | B10: 41229.074 | C10: 29683.03 | D10: 17605.8 | E10: 47288.83
A11: 46552 | B11: 10293.844 | C11: 30935.23 | D11: 14697.99 | E11: 45633.22
A12: 46552 | B12: 0.0040000001 | C12: 10293.84 | D12: 0 | E12: 10293.84

Sheet 2010013918
A1: Fecha | B1: Saldo adeudado | C1: Amortización | D1: Intereses corrientes | E1: Total Cuota
A2: 45742 | B2: 346343.01 | C2: 0 | D2: 0 | E2: 0
A3: 45832 | B3: 309433.84 | C3: 36909.17 | D3: 4285.87 | E3: 41195.04
A4: 45922 | B4: 271740.35 | C4: 37693.49 | D4: 3732.23 | E4: 41425.72
A5: 46012 | B5: 233245.87 | C5: 38494.48 | D5: 3166.83 | E5: 41661.31
A6: 46102 | B6: 193933.38 | C6: 39312.49 | D6: 2589.41 | E6: 41901.9
A7: 46192 | B7: 153785.5 | C7: 40147.88 | D7: 1999.73 | E7: 42147.61
A8: 46282 | B8: 112784.48 | C8: 41001.02 | D8: 1397.51 | E8: 42398.53
A9: 46372 | B9: 70912.104 | C9: 41872.38 | D9: 782.49 | E9: 42654.87
A10: 46462 | B10: 41229.074 | C10: 29683.03 | D10: 17605.8 | E10: 47288.83
A11: 46552 | B11: 10293.844 | C11: 30935.23 | D11: 14697.99 | E11: 45633.22
A12: 46552 | B12: 0.0040000001 | C12: 10293.84 | D12: 0 | E12: 10293.84

Sheet 2010014218
A1: Fecha | B1: Saldo adeudado | C1: Amortización | D1: Intereses corrientes | E1: Total Cuota
A2: 45742 | B2: 346343.01
A3: 45832 | B3: 309433.84 | C3: 36909.17 | D3: 4285.87 | E3: 41195.04
A4: 45922 | B4: 271740.35 | C4: 37693.49 | D4: 3732.23 | E4: 41425.72
A5: 46012 | B5: 233245.87 | C5: 38494.48 | D5: 3166.83 | E5: 41661.31
A6: 46102 | B6: 193933.38 | C6: 39312.49 | D6: 2589.41 | E6: 41901.9
A7: 46192 | B7: 153785.5 | C7: 40147.88 | D7: 1999.73 | E7: 42147.61
A8: 46282 | B8: 112784.48 | C8: 41001.02 | D8: 1397.51 | E8: 42398.53
A9: 46372 | B9: 70912.104 | C9: 41872.38 | D9: 782.49 | E9: 42654.87
A10: 46462 | B10: 41229.074 | C10: 29683.03 | D10: 17605.8 | E10: 47288.83
A11: 46552 | B11: 10293.844 | C11: 30935.23 | D11: 14697.99 | E11: 45633.22
A12: 46552 | B12: 0.0040000001 | C12: 10293.84 | D12: 0 | E12: 10293.84

Sheet 2010014318
A1: Fecha | B1: Saldo adeudado | C1: Amortización | D1: Intereses corrientes | E1: Total Cuota
A2: 45724 | B2: 426409.54
A3: 45814 | B3: 388403.55 | C3: 38005.99 | D3: 5069.14 | E3: 43075.13
A4: 45904 | B4: 349589.93 | C4: 38813.62 | D4: 4499.05 | E4: 43312.67
A5: 45994 | B5: 309951.52 | C5: 39638.41 | D5: 3916.84 | E5: 43555.25
A6: 46084 | B6: 269470.8 | C6: 40480.72 | D6: 3322.26 | E6: 43802.98
A7: 46174 | B7: 228129.86 | C7: 41340.94 | D7: 2715.05 | E7: 44055.99
A8: 46264 | B8: 185910.43 | C8: 42219.43 | D8: 2094.94 | E8: 44314.37
A9: 46354 | B9: 142793.83 | C9: 43116.6 | D9: 1461.65 | E9: 44578.25
A10: 46444 | B10: 98761.04 | C10: 44032.79 | D10: 814.9 | E10: 44847.69
A11: 46534 | B11: 70279.53 | C11: 28481.51 | D11: 18828.9 | E11: 47310.41
A12: 46624 | B12: 40596.5 | C12: 29683.03 | D12: 12324.06 | E12: 42007.09
A13: 46714 | B13: 10293.84 | C13: 30302.66 | D13: 16975.03 | E13: 47277.69
A14: 46714 | B14: 4.3655746e-11 | C14: 10293.84 | E14: 10293.84

Sheet 2010014018
A1: Fecha | B1: Saldo adeudado | C1: Amortización | D1: Intereses corrientes | E1: Total Cuota
A2: 45724 | B2: 426409.54
A3: 45814 | B3: 388403.55 | C3: 38005.99 | D3: 5069.14 | E3: 43075.13
A4: 45904 | B4: 349589.93 | C4: 38813.62 | D4: 4499.05 | E4: 43312.67
A5: 45994 | B5: 309951.52 | C5: 39638.41 | D5: 3916.84 | E5: 43555.25
A6: 46084 | B6: 269470.8 | C6: 40480.72 | D6: 3322.26 | E6: 43802.98
A7: 46174 | B7: 228129.86 | C7: 41340.94 | D7: 2715.05 | E7: 44055.99
A8: 46264 | B8: 185910.43 | C8: 42219.43 | D8: 2094.94 | E8: 44314.37
A9: 46354 | B9: 142793.83 | C9: 43116.6 | D9: 1461.65 | E9: 44578.25
A10: 46444 | B10: 98761.04 | C10: 44032.79 | D10: 814.9 | E10: 44847.69
A11: 46534 | B11: 70279.53 | C11: 28481.51 | D11: 18828.9 | E11: 47310.41
A12: 46624 | B12: 40596.5 | C12: 29683.03 | D12: 12324.06 | E12: 42007.09
A13: 46714 | B13: 10293.84 | C13: 30302.66 | D13: 16975.03 | E13: 47277.69
A14: 46714 | B14: 4.3655746e-11 | C14: 10293.84 | E14: 10293.84

Sheet Garantias
A1: numero operación | B1: Entidad Financiera | C1: numero de contrato | D1: =+Caracteristicas!D1 -> Moneda | E1: =+Caracteristicas!E1 -> Tasa | F1: =+Caracteristicas!F1 -> Periodicidad | G1: =+Caracteristicas!H1 -> vencimiento | H1: =+Caracteristicas!K1 -> Saldo a capital | I1: =+Caracteristicas!L1 -> % adeudado por Cemento | J1: =+Caracteristicas!M1 -> Saldo a capital Cemento | K1: existencias de mercaderia | L1: detalle existencia de mercaderia | M1: prendaria | N1: detalle prendaria | O1: hipotecaria | P1: detalle hipotecaria | Q1: covenants | R1: total
A2: =+Caracteristicas!A2 -> 3167401 | B2: =+Caracteristicas!B2 -> Fideicomiso - Banco Unión | C2: Testimonio XXX/2024 | K2: 840000 | L2: Bolsas de 50 kg de cemento y clinker tipo IP 30 | M2: 2.3678982e+08 | N2: - maquinaria ubicada en Irpa Irpa, según avaluo de fecha 24 de abril de 2023, elaborado por CIDEAR | Q2: - Entregar infromación finacniera de maenra semestral debiendo presentar EEFF fiscales auditados hasta agosto de cada gestión. - No realizar distribuciones, pago de dividendos, inversiones en empresas relacionadas, o cualquier forma de pago de crédito o ingresos a favor de sus asociados - en 360 dias vender las acciones de las empresas en las que tenga participación y sean ajenas al giro de su negocio, aplicados a reducir la obligacion presente. - Trimestralmente presentar un informe debidamente firmado por Gerencia General que incluya un resumen de las gestiones comerciales realizadas para concretar la venta de las acciones | R2: =+SUM(K2:Q2) -> 2.3762982e+08
A3: =+Caracteristicas!#REF! -> #REF! | B3: =+Caracteristicas!#REF! -> #REF! | C3: Testimonio 1007/2023 | N3: - Una torre de precalcinación DOPOL, planta Irpa Irpa. - 10 toneladas de Clinker, playas de almacenamiento Irpa Irpa | P3: - Lote de terreno extensión 2762,74 m2, ubicación Tadeo Haenke. - Lote de terreno extensión 143737,22 m2, ubicación PILAT Warnes

Sheet Obligaciones financieras
N1: Nro de la operación | Q1: 3167401 | AE1: Nro de la operación | AG1: 2767412 | AT1: Nro de la operación | AV1: 2764418 | BI1: Nro de la operación | BK1: 1271559 | BY1: Nro de la operación | CA1: 1358960 | CP1: Nro de la operación | CR1: 1295150 | CY1: Nro de la operación | DA1: 101243178 | DN1: Nro de la operación | DP1: 315101121500077 | EC1: Nro de la operación | EE1: 315101121500078f | FA1: Nro de la operación | FC1: 315101121500021 | FK1: Nro de la operación | FM1: 2010014418 | FT1: Nro de la operación | FV1: 2010014118 | GC1: Nro de la operación | GE1: 2010013918 | GL1: Nro de la operación | GN1: 2010014218 | GU1: Nro de la operación | GW1: 2010014318 | HD1: Nro de la operación | HF1: 2010014018
N2: Entidad | Q2: Fideicomiso - Banco Unión | AE2: Entidad | AG2: Banco Unión | AT2: Entidad | AV2: Banco Unión | BI2: Entidad | BK2: Banco Bisa | BY2: Entidad | CA2: Banco Bisa | CP2: Entidad | CR2: Banco Bisa | CY2: Entidad | DA2: Banco Ganadero | DN2: Entidad | DP2: Banco de Desarrollo Productivo | EC2: Entidad | EE2: Banco de Desarrollo Productivo | FA2: Entidad | FC2: Banco de Desarrollo Productivo | FK2: Entidad | FM2: BNB leasing | FT2: Entidad | FV2: BNB leasing | GC2: Entidad | GE2: BNB leasing | GL2: Entidad | GN2: BNB leasing | GU2: Entidad | GW2: BNB leasing | HD2: Entidad | HF2: BNB leasing
N3: Cod. Entidad | Q3: FID - BUN | AE3: Cod. Entidad | AG3: BUN | AT3: Cod. Entidad | AV3: BUN | BI3: Cod. Entidad | BK3: BIS | BY3: Cod. Entidad | CA3: BIS | CP3: Cod. Entidad | CR3: BIS | CY3: Cod. Entidad | DA3: GAN | DN3: Cod. Entidad | DP3: BDP | EC3: Cod. Entidad | EE3: BDP | FA3: Cod. Entidad | FC3: BDP | FK3: Cod. Entidad | FM3: BNL | FT3: Cod. Entidad | FV3: BNL | GC3: Cod. Entidad | GE3: BNL | GL3: Cod. Entidad | GN3: BNL | GU3: Cod. Entidad | GW3: BNL | HD3: Cod. Entidad | HF3: BNL
N4: Moneda | Q4: Bolivanos | AE4: Moneda | AG4: Bolivanos | AT4: Moneda | AV4: Bolivanos | BI4: Moneda | BK4: Bolivanos | BY4: Moneda | CA4: Bolivanos | CP4: Moneda | CR4: Bolivanos | CY4: Moneda | DA4: Bolivanos | DN4: Moneda | DP4: Bolivanos | EC4: Moneda | EE4: Bolivanos | FA4: Moneda | FC4: Bolivanos | FK4: Moneda | FM4: Bolivanos | FT4: Moneda | FV4: Bolivanos | GC4: Moneda | GE4: Bolivanos | GL4: Moneda | GN4: Bolivanos | GU4: Moneda | GW4: Bolivanos | HD4: Moneda | HF4: Bolivanos
N5: Tasa | Q5: 0.06 | AE5: Tasa | AG5: 0.055 | AT5: Tasa | AV5: 0.06 | BI5: Tasa | BK5: 0.06 | BY5: Tasa | CA5: 0.06 | CP5: Tasa | CR5: 0.06 | CY5: Tasa | DA5: 0.06 | DN5: Tasa | DP5: 0.058 | EC5: Tasa | EE5: 0.0582 | FA5: Tasa | FC5: 0.0599 | FK5: Tasa | FM5: 0.06 | FT5: Tasa | FV5: 0.06 | GC5: Tasa | GE5: 0.06 | GL5: Tasa | GN5: 0.06 | GU5: Tasa | GW5: 0.06 | HD5: Tasa | HF5: 0.06
N6: Periodicidad | Q6: Trimestral | AE6: Periodicidad | AG6: Trimestral | AT6: Periodicidad | AV6: Trimestral | BI6: Periodicidad | BK6: Trimestral | BY6: Periodicidad | CA6: Trimestral | CP6: Periodicidad | CR6: Trimestral | CY6: Periodicidad | DA6: Mensual | DN6: Periodicidad | DP6: Trimestral | EC6: Periodicidad | EE6: Trimestral | FA6: Periodicidad | FC6: Trimestral | FK6: Periodicidad | FM6: Trimestral | FT6: Periodicidad | FV6: Trimestral | GC6: Periodicidad | GE6: Trimestral | GL6: Periodicidad | GN6: Trimestral | GU6: Periodicidad | GW6: Trimestral | HD6: Periodicidad | HF6: Trimestral
N7: inicio
N8: vencimiento | Q8: =+MAX(O25:O822) -> 48248 | AE8: vencimiento | AG8: =+MAX(AE25:AE822) -> 48058 | AT8: vencimiento | AV8: =+MAX(AT25:AT822) -> 48997 | BI8: vencimiento | BK8: =+MAX(BI25:BI822) -> 47107 | BY8: vencimiento | CA8: =+MAX(BY25:BY822) -> 47398 | CC8: =4596722.94+169631.13+115779.85 -> 4882133.9 | CP8: vencimiento | CR8: =+MAX(CP25:CP822) -> 47375 | CY8: vencimiento | DA8: =+MAX(CY25:CY822) -> 46609 | DN8: vencimiento | DP8: =+MAX(DN25:DN822) -> 49111 | EC8: vencimiento | EE8: =+MAX(EC25:EC822) -> 48765 | FA8: vencimiento | FC8: =+MAX(FA25:FA822) -> 49111 | FK8: vencimiento | FM8: =+MAX(FK25:FK822) -> 46552 | FT8: vencimiento | FV8: =+MAX(FT25:FT822) -> 46552 | GC8: vencimiento | GE8: =+MAX(GC25:GC822) -> 46552 | GL8: vencimiento | GN8: =+MAX(GL25:GL822) -> 46552 | GU8: vencimiento | GW8: =+MAX(GU25:GU822) -> 46714 | HD8: vencimiento | HF8: =+MAX(HD25:HD822) -> 46714
N9: plazo | Q9: =+Q8-[1]Caracteristicas!$B$19 -> 2348 | AG9: =+AG8-[1]Caracteristicas!$B$19 -> 2158 | AV9: =+AV8-[1]Caracteristicas!$B$19 -> 3097 | BK9: =+BK8-[1]Caracteristicas!$B$19 -> 1207 | CA9: =+CA8-[1]Caracteristicas!$B$19 -> 1498 | CR9: =+CR8-[1]Caracteristicas!$B$19 -> 1475 | DA9: =+DA8-[1]Caracteristicas!$B$19 -> 709 | DP9: =+DP8-[1]Caracteristicas!$B$19 -> 3211 | EE9: =+EE8-[1]Caracteristicas!$B$19 -> 2865 | FC9: =+FC8-[1]Caracteristicas!$B$19 -> 3211 | FM9: =+FM8-[1]Caracteristicas!$B$19 -> 652 | FV9: =+FV8-[1]Caracteristicas!$B$19 -> 652 | GE9: =+GE8-[1]Caracteristicas!$B$19 -> 652 | GN9: =+GN8-[1]Caracteristicas!$B$19 -> 652 | GW9: =+GW8-[1]Caracteristicas!$B$19 -> 814 | HF9: =+HF8-[1]Caracteristicas!$B$19 -> 814
N10: Saldo a capital inicial
N11: Saldo Adeudado | Q11: =+Q13/Q12 -> 2.3034329e+08 | AG11: =+AG13/AG12 -> 1241907.9 | AV11: =+AV13/AV12 -> 51796168 | BK11: =+BK13/BK12 -> 53476614 | CA11: =+CA13/CA12 -> 4571867.8 | CR11: =+CR13/CR12 -> 1669085.9 | DA11: =+DA13/DA12 -> 29810000 | DP11: =+DP13/DP12 -> 9174681.5 | EE11: =+EE13/EE12 -> 8467855 | FC11: =+FC13/FC12 -> 2794681.5 | FM11: =+FM13/FM12 -> 309433.84 | FV11: =+FV13/FV12 -> 309433.84 | GE11: =+GE13/GE12 -> 309433.84 | GN11: =+GN13/GN12 -> 309433.84 | GW11: =+GW13/GW12 -> 388403.55 | HF11: =+HF13/HF12 -> 388403.55
N12: % correspondiente a CEMENTO | Q12: 0.57390185 | AE12: % correspondiente a CEMENTO | AG12: 1 | AT12: % correspondiente a CEMENTO | AV12: =+AV13/AV15 -> 0.3088359 | BI12: % correspondiente a CEMENTO | BK12: 1 | BY12: % correspondiente a CEMENTO | CA12: =+CB27/254312.71 -> 0.22702943 | CP12: % correspondiente a CEMENTO | CR12: 1 | CY12: % correspondiente a CEMENTO | DA12: =++DA13/DA15 -> 0.86082018 | DN12: % correspondiente a CEMENTO | DP12: 0.99370812 | EC12: % correspondiente a CEMENTO | EE12: =+EE13/EE15 -> 0.13104947 | EF12: Antes | EH12: 0.38897016 | FA12: % correspondiente a CEMENTO | FC12: 1 | FK12: % correspondiente a CEMENTO | FM12: 1 | FT12: % correspondiente a CEMENTO | FV12: 1 | GC12: % correspondiente a CEMENTO | GE12: 1 | GL12: % correspondiente a CEMENTO | GN12: 1 | GU12: % correspondiente a CEMENTO | GW12: 1 | GY12: 100 | HD12: % correspondiente a CEMENTO | HF12: 1
N13: Saldo Adeudado CEMENTO | Q13: =+Q29 -> 1.3219444e+08 | AE13: Saldo Adeudado CEMENTO | AG13: =+AG27 -> 1241907.9 | AT13: Saldo Adeudado CEMENTO | AV13: =+AV28 -> 15996516 | BI13: Saldo Adeudado CEMENTO | BK13: =+BK26 -> 53476614 | BY13: Saldo Adeudado CEMENTO | CA13: =+CA28+CC24 -> 1037948.5 | CP13: Saldo Adeudado CEMENTO | CR13: =+CR26 -> 1669085.9 | CY13: Saldo Adeudado CEMENTO | DA13: =+DA26 -> 25661049 | DN13: Saldo Adeudado CEMENTO | DP13: =+DP26 -> 9116955.5 | EC13: Saldo Adeudado CEMENTO | EE13: =+EE25 -> 1109707.9 | EF13: Transferencia a CERAMIL | EH13: =+EH12*EE11 -> 3293742.9 | EI13: =+EH13-EE13 -> 2184035 | FA13: Saldo Adeudado CEMENTO | FC13: =+FC27 -> 2794681.5 | FK13: Saldo Adeudado CEMENTO | FM13: =+FM26 -> 309433.84 | FT13: Saldo Adeudado CEMENTO | FV13: =+FV26 -> 309433.84 | GC13: Saldo Adeudado CEMENTO | GE13: =+GE26 -> 309433.84 | GL13: Saldo Adeudado CEMENTO | GN13: =+GN26 -> 309433.84 | GU13: Saldo Adeudado CEMENTO | GW13: =+GW26 -> 388403.55 | GY13: =+GY12/13.8 -> 7.2463768 | HD13: Saldo Adeudado CEMENTO | HF13: =+HF26 -> 388403.55
N14: Monto desembolsado
N15: Total de Saldo Adeudado | Q15: 2.3061769e+08 | AE15: Total de Saldo Adeudado | AG15: =+AG12*AG13 -> 1241907.9 | AT15: Total de Saldo Adeudado | AV15: =+SUM([2]Consolidado1!$C$241:$C$245) -> 51796168 | AY15: =187920.41+6784.89+626.79 -> 195332.09 | BI15: Total de Saldo Adeudado | BK15: =+BK25 -> 53476614 | BY15: Total de Saldo Adeudado | CA15: =+CA13/CA12 -> 4571867.8 | CP15: Total de Saldo Adeudado | CR15: 1460450.1 | CY15: Total de Saldo Adeudado | DA15: =+SUM([2]Consolidado1!$C$323:$C$328) -> 29810000 | DN15: Total de Saldo Adeudado | DP15: =+DP13/DP12 -> 9174681.5 | EC15: Total de Saldo Adeudado | EE15: =+SUM([2]Consolidado1!$C$315:$C$319) -> 8467855 | FA15: Total de Saldo Adeudado | FK15: Total de Saldo Adeudado | FM15: 346343.01 | FT15: Total de Saldo Adeudado | FV15: 346343.01 | GC15: Total de Saldo Adeudado | GE15: 346343.01 | GL15: Total de Saldo Adeudado | GN15: 346343.01 | GU15: Total de Saldo Adeudado | GW15: 426409.54 | HD15: Total de Saldo Adeudado | HF15: 426409.54
N16: Total de Intereses Diferidos | Q16: 16433143 | AE16: Total de Intereses Diferidos | AT16: Total de Intereses Diferidos | BI16: Total de Intereses Diferidos | BY16: Total de Intereses Diferidos | CP16: Total de Intereses Diferidos | CY16: Total de Intereses Diferidos | DN16: Total de Intereses Diferidos | EC16: Total de Intereses Diferidos | FA16: Total de Intereses Diferidos | FK16: Total de Intereses Diferidos | FT16: Total de Intereses Diferidos | GC16: Total de Intereses Diferidos | GL16: Total de Intereses Diferidos | GU16: Total de Intereses Diferidos | HD16: Total de Intereses Diferidos
N17: Intereses DIferidos CEMENTO | Q17: =+Q16*Q12 -> 9431010.9 | AE17: Intereses DIferidos CEMENTO | AT17: Intereses DIferidos CEMENTO | BI17: Intereses DIferidos CEMENTO | BY17: Intereses DIferidos CEMENTO | CP17: Intereses DIferidos CEMENTO | CY17: Intereses DIferidos CEMENTO | DN17: Intereses DIferidos CEMENTO | EC17: Intereses DIferidos CEMENTO | FA17: Intereses DIferidos CEMENTO | FK17: Intereses DIferidos CEMENTO | FT17: Intereses DIferidos CEMENTO | GC17: Intereses DIferidos CEMENTO | GL17: Intereses DIferidos CEMENTO | GU17: Intereses DIferidos CEMENTO | HD17: Intereses DIferidos CEMENTO
N18: # Cuotas Intereses Diferidos | Q18: 20 | AE18: # Cuotas Intereses Diferidos | AT18: # Cuotas Intereses Diferidos | BI18: # Cuotas Intereses Diferidos | BY18: # Cuotas Intereses Diferidos | CP18: # Cuotas Intereses Diferidos | CY18: # Cuotas Intereses Diferidos | DN18: # Cuotas Intereses Diferidos | EC18: # Cuotas Intereses Diferidos | FA18: # Cuotas Intereses Diferidos | FK18: # Cuotas Intereses Diferidos | FT18: # Cuotas Intereses Diferidos | GC18: # Cuotas Intereses Diferidos | GL18: # Cuotas Intereses Diferidos | GU18: # Cuotas Intereses Diferidos | HD18: # Cuotas Intereses Diferidos
N19: Amortización Trimenstral 1er Año | Q19: 68600 | AE19: Amortización Trimenstral | AG19: 51840.79 | AT19: Amortización Trimenstral | AV19: 51840.79 | BI19: Amortización Trimenstral | BK19: 51840.79 | BY19: Amortización Trimenstral | CA19: =+CB26 -> 57736.47 | CP19: Amortización Trimenstral | CY19: Amortización Trimenstral | DN19: Amortización Trimenstral | EC19: Amortización Trimenstral | FA19: Amortización Trimenstral | FK19: Amortización Trimenstral | FT19: Amortización Trimenstral | GC19: Amortización Trimenstral | GL19: Amortización Trimenstral | GU19: Amortización Trimenstral | HD19: Amortización Trimenstral
N20: Amort. Trim 1er año CEMENTO | Q20: =+Q19*Q12 -> 39369.667
N21: Amortización 5to trimestre | Q21: 30369494
A23: N | B23: semana | C23: Dia | D23: Desembolsos | E23: Saldo adeudado | F23: Capital | G23: Intereses | H23: Total Cuota | I23: Por pagar | J23: Entidad | M23: N | N23: Fin mes | O23: Fecha | P23: Desembolsos | Q23: Saldo adeudado | R23: Amortización | S23: Intereses corrientes | T23: Intereses diferidos | U23: Total Cuota | V23: Número de cuota | W23: fecha de pago | X23: dias de mora | Y23: pago a capital | Z23: intereses corrientes | AA23: cuota pagada | AC23: N | AD23: Fin mes | AE23: Fecha | AF23: Desembolsos | AG23: Saldo adeudado | AH23: Amortización | AI23: Intereses corrientes | AJ23: Total Cuota | AK23: Número de cuota | AL23: fecha de pago | AM23: pago a capital | AN23: intereses corrientes | AO23: cuota pagada | AR23: N | AS23: Fin mes | AT23: Fecha | AU23: Desembolsos | AV23: Saldo adeudado | AW23: Amortización | AX23: Intereses corrientes | AY23: Total Cuota | AZ23: Número de cuota | BA23: fecha de pago | BB23: dias de mora | BC23: pago a capital | BD23: intereses corrientes | BE23: cuota pagada | BG23: N | BH23: Fin mes | BI23: Fecha | BJ23: Desembolsos | BK23: Saldo adeudado | BL23: Amortización | BM23: Intereses corrientes | BN23: Interes prorroga y gracia | BO23: Total Cuota | BP23: Número de cuota | BQ23: fecha de pago | BR23: dias de mora | BS23: pago a capital | BT23: intereses corrientes | BU23: cuota pagada | BW23: N | BX23: Fin mes | BY23: Fecha | BZ23: Desembolsos | CA23: Saldo adeudado | CB23: Amortización | CC23: Amortización cap diferido | CD23: Intereses corrientes | CE23: Intereses prorroga gracia | CF23: Total Cuota | CG23: Número de cuota | CH23: fecha de pago | CI23: dias de mora | CJ23: pago a capital | CK23: intereses corrientes | CL23: cuota pagada | CN23: N | CO23: Fin mes | CP23: Fecha | CQ23: Desembolsos | CR23: Saldo adeudado | CS23: Amortización | CT23: Intereses corrientes | CU23: Total Cuota | CW23: N | CX23: Fin mes | CY23: Fecha | CZ23: Desembolsos | DA23: Saldo adeudado | DB23: Amortización | DC23: Intereses corrientes | DD23: Total Cuota | DE23: Número de cuota | DF23: fecha de pago | DG23: dias de mora | DH23: pago a capital | DI23: intereses corrientes | DJ23: cuota pagada | DL23: N | DM23: Fin mes | DN23: Fecha | DO23: Desembolsos | DP23: Saldo adeudado | DQ23: Amortización | DR23: Intereses corrientes | DS23: Total Cuota | DT23: Número de cuota | DU23: fecha de pago | DV23: dias de mora | DW23: pago a capital | DX23: intereses corrientes | DY23: cuota pagada | EA23: N | EB23: Fin mes | EC23: Fecha | ED23: Desembolsos | EE23: Saldo adeudado | EF23: Amortización | EG23: Intereses corrientes | EH23: Total Cuota | EI23: Número de cuota | EJ23: fecha de pago | EK23: dias de mora | EL23: pago a capital | EM23: intereses corrientes | EN23: cuota pagada | EY23: N | EZ23: Fin mes | FA23: Fecha | FB23: Desembolsos | FC23: Saldo adeudado | FD23: Amortización | FE23: Intereses corrientes | FF23: Intereses prorroga gracia | FG23: Total Cuota | FI23: N | FJ23: Fin mes | FK23: Fecha | FL23: Desembolsos | FM23: Saldo adeudado | FN23: Amortización | FO23: Intereses corrientes | FP23: Total Cuota | FR23: N | FS23: Fin mes | FT23: Fecha | FU23: Desembolsos | FV23: Saldo adeudado | FW23: Amortización | FX23: Intereses corrientes | FY23: Total Cuota | GA23: N | GB23: Fin mes | GC23: Fecha | GD23: Desembolsos | GE23: Saldo adeudado | GF23: Amortización | GG23: Intereses corrientes | GH23: Total Cuota | GJ23: N | GK23: Fin mes | GL23: Fecha | GM23: Desembolsos | GN23: Saldo adeudado | GO23: Amortización | GP23: Intereses corrientes | GQ23: Total Cuota | GS23: N | GT23: Fin mes | GU23: Fecha | GV23: Desembolsos | GW23: Saldo adeudado | GX23: Amortización | GY23: Intereses corrientes | GZ23: Total Cuota | HB23: N | HC23: Fin mes | HD23: Fecha | HE23: Desembolsos | HF23: Saldo adeudado | HG23: Amortización | HH23: Intereses corrientes | HI23: Total Cuota
F24: =+SUM(F26:F1150) -> 58844181 | G24: =+SUM(G26:G1150) -> 22585088 | R24: =+SUM(R30:R1150) -> 1.3219444e+08 | AH24: =+SUM(AH28:AH1150) -> 1241907.9 | AW24: =+SUM(AW29:AW1150) -> 15996516 | BL24: =+SUM(BL29:BL1150) -> 42476614 | CB24: =+SUM(CB28:CB1150) -> 1039256.4 | CC24: =+SUM(CC29:CC1150) -> 56428.57 | CS24: =+SUM(CS28:CS1150) -> 1669085.9 | DB24: =+SUM(DB27:DB1150) -> 25661049 | DQ24: =+SUM(DQ27:DQ1150) -> 9116955.5 | EF24: =+SUM(EF27:EF1150) -> 1109708 | FD24: =+SUM(FD27:FD1150) -> 2794681.5 | FN24: =+SUM(FN27:FN1150) -> 309433.84 | FW24: =+SUM(FW27:FW1150) -> 309433.84 | GF24: =+SUM(GF27:GF1150) -> 309433.84 | GO24: =+SUM(GO27:GO1150) -> 309433.84 | GX24: =+SUM(GX27:GX1150) -> 388403.55 | HG24: =+SUM(HG27:HG1150) -> 388403.55
A25: 0 | B25: =+WEEKNUM(C25,2) -> 14 | C25: 45747 | E25: =+SUM(F26:F1150) -> 58844181 | M25: 0 | N25: =+EOMONTH(O25,0) -> 45535 | O25: 45506 | P25: =+Q13 -> 1.3219444e+08 | Q25: 1.3235192e+08 | AC25: 0 | AD25: =+EOMONTH(AE25,0) -> 45716 | AE25: 45712 | AG25: 1345589.5 | AR25: 0 | AS25: =+EOMONTH(AT25,0) -> 45657 | AT25: 45656 | AV25: 15996516 | BG25: 0 | BH25: =+EOMONTH(BI25,0) -> 45747 | BI25: 45736 | BK25: 53476614 | BW25: 0 | BX25: =+EOMONTH(BY25,0) -> 45688 | BY25: 45677 | CA25: 1154729.4 | CN25: 0 | CO25: =+EOMONTH(CP25,0) -> 45716 | CP25: 45700 | CR25: 1669085.9 | CW25: 0 | CX25: =+EOMONTH(CY25,0) -> 45869 | CY25: 45848 | DA25: 26010061 | DL25: 0 | DM25: =+EOMONTH(DN25,0) -> 45747 | DN25: 45721 | DP25: 9116955.5 | EA25: 0 | EB25: =+EOMONTH(EC25,0) -> 45747 | EC25: 45721 | EE25: 1109707.9 | EY25: 0 | EZ25: =+EOMONTH(FA25,0) -> 45657 | FA25: 45657 | FC25: 2794681.5 | FI25: 0 | FJ25: =+EOMONTH(FK25,0) -> 45747 | FK25: =+FK26-90 -> 45742 | FM25: 346343.01 | FR25: 0 | FS25: =+EOMONTH(FT25,0) -> 45747 | FT25: =+FT26-90 -> 45742 | FV25: 346343.01 | GA25: 0 | GB25: =+EOMONTH(GC25,0) -> 45747 | GC25: =+GC26-90 -> 45742 | GE25: 346343.01 | GJ25: 0 | GK25: =+EOMONTH(GL25,0) -> 45747 | GL25: =+GL26-90 -> 45742 | GN25: 346343.01 | GS25: 0 | GT25: =+EOMONTH(GU25,0) -> 45747 | GU25: =+GU26-90 -> 45724 | GW25: 426409.54 | HB25: 0 | HC25: =+EOMONTH(HD25,0) -> 45747 | HD25: 45724 | HF25: 426409.54
A26: 1 | B26: =+WEEKNUM(C26,2) -> 18 | C26: =+EOMONTH(C25,1) -> 45777 | E26: =+E25+D26-F26 -> 58844181 | F26: =+SUMIF(N:N,C26,R:R)+SUMIF(AD:AD,C26,AH:AH)+SUMIF(AS:AS,C26,AW:AW)+SUMIF(BH:BH,C26,BL:BL)+SUMIF(BX:BX,C26,CB:CB)+SUMIF(BX:BX,C26,CC:CC)+SUMIF(CO:CO,C26,CS:CS)+SUMIF(CX:CX,C26,DB:DB)+SUMIF(DM:DM,C26,DQ:DQ)+SUMIF(EB:EB,C26,EF:EF)+SUMIF(EQ:EQ,C26,EU:EU)+SUMIF(EZ:EZ,C26,FD:FD)+SUMIF(FJ:FJ,C26,FN:FN)+SUMIF(FS:FS,C26,FW:FW)+SUMIF(GB:GB,C26,GF:GF)+SUMIF(GK:GK,C26,GO:GO)+SUMIF(GT:GT,C26,GX:GX)+SUMIF(HC:HC,C26,HG:HG) -> 0 | G26: =+SUMIF(N:N,C26,T:T)+SUMIF(N:N,C26,S:S)+SUMIF(AD:AD,C26,AI:AI)+SUMIF(AS:AS,C26,AX:AX)+SUMIF(BH:BH,C26,BN:BN)+SUMIF(BH:BH,C26,BM:BM)+SUMIF(BX:BX,C26,CD:CD)+SUMIF(BX:BX,C26,CE:CE)+SUMIF(CO:CO,C26,CT:CT)+SUMIF(CX:CX,C26,DC:DC)+SUMIF(DM:DM,C26,DR:DR)+SUMIF(EB:EB,C26,EG:EG)+SUMIF(EQ:EQ,C26,EV:EV)+SUMIF(EZ:EZ,C26,FE:FE)+SUMIF(FJ:FJ,C26,FO:FO)+SUMIF(FS:FS,C26,FX:FX)+SUMIF(GB:GB,C26,GG:GG)+SUMIF(GK:GK,C26,GP:GP)+SUMIF(GT:GT,C26,GY:GY)+SUMIF(HC:HC,C26,HH:HH) -> 0 | H26: =+SUM(F26:G26) -> 0 | M26: 1 | N26: =+EOMONTH(O26,0) -> 45626 | O26: 45611 | Q26: =+Q25-R26 -> 1.3231255e+08 | R26: =+$Q$20 -> 39369.667 | S26: =+Q25*Q$5*(O26-O25)/360 -> 2316158.6 | T26: =+$Q$17/$Q$18 -> 471550.55 | U26: =+SUM(R26:T26) -> 2827078.8 | AC26: 1 | AD26: =+EOMONTH(AE26,0) -> 45808 | AE26: 45779 | AG26: =+AG25+AF26-AH26 -> 1293748.7 | AH26: =+AG19 -> 51840.79 | AI26: =+AG25*AG$5*(AE26-AE25)/360 -> 13773.604 | AJ26: =+SUM(AH26:AI26) -> 65614.394 | AK26: 1 | AL26: 45796 | AM26: =+AH26 -> 51840.79 | AN26: =+AG25*AG$5*(AL26-AE25)/360 -> 17268.399 | AO26: =+AN26+AM26 -> 69109.189 | AR26: 1 | AS26: =+EOMONTH(AT26,0) -> 45716 | AT26: 45708 | AV26: 15996516 | AW26: 0 | AX26: =+AV25*AV$5*(AT26-AT25)/360 -> 138636.47 | AY26: =+SUM(AW26:AX26) -> 138636.47 | AZ26: 1 | BA26: 45744 | BB26: =+BA26-AT26 -> 36 | BC26: =+AW26 -> 0 | BD26: =+AV25*AV$5*(BA26-AT25)/360 -> 234615.57 | BE26: =+BD26+BC26 -> 234615.57 | BG26: 1 | BH26: =+EOMONTH(BI26,0) -> 45838 | BI26: 45828 | BK26: =+BK25+BJ26-BL26 -> 53476614 | BL26: 0 | BM26: =+BK25*BK$5*(BI26-BI25)/360 -> 819974.75 | BN26: 82616.23 | BO26: =+SUM(BL26:BN26) -> 902590.98 | BP26: 1 | BQ26: 45828 | BS26: =+BL26 -> 0 | BT26: =+BK25*BK$5*(BQ26-BI25)/360 -> 819974.75 | BU26: =+BT26+BS26+BN26 -> 902590.98 | BW26: 1 | BX26: =+EOMONTH(BY26,0) -> 45716 | BY26: 45702 | CA26: =+CA25+BZ26-CB26 -> 1096992.9 | CB26: 57736.47 | CC26: 0 | CD26: =+CA25*CA$5*(BY26-BY25)/360 -> 4811.3725 | CE26: 1642.8395 | CF26: =+SUM(CB26:CE26) -> 64190.682 | CG26: 1 | CH26: 45702 | CJ26: =+CB26 -> 57736.47 | CK26: =+CA25*CA$5*(CH26-BY25)/360 -> 4811.3725 | CL26: =+CK26+CJ26+CE26 -> 64190.682 | CN26: 1 | CO26: =+EOMONTH(CP26,0) -> 45838 | CP26: 45822 | CR26: =+CR25+CQ26-CS26 -> 1669085.9 | CS26: 0 | CT26: 29209.003 | CU26: =+SUM(CS26:CT26) -> 29209.003 | CW26: 1 | CX26: =+EOMONTH(CY26,0) -> 45900 | CY26: 45879 | DA26: =+DA25+CZ26-DB26 -> 25661049 | DB26: 349011.21 | DC26: =+DA25*DA$5*(CY26-CY25)/360 -> 134385.31 | DD26: =+SUM(DB26:DC26) -> 483396.52 | DE26: 1 | DF26: =+CY26 -> 45879 | DH26: =+CZ26 -> 0 | DI26: =+CY25*CY$5*(DF26-CW25)/360 -> #VALUE! | DJ26: =+DI26+DH26+DC26 -> #VALUE! | DL26: 1 | DM26: =+EOMONTH(DN26,0) -> 45838 | DN26: 45838 | DP26: =+DP25+DO26-DQ26 -> 9116955.5 | DQ26: 0 | DR26: 138152.48 | DS26: =+SUM(DQ26:DR26) -> 138152.48 | DT26: 1 | DU26: =+DN26 -> 45838 | DW26: =+DO26 -> 0 | DX26: =+DN25*DN$5*(DU26-DL25)/360 -> #VALUE! | DY26: =+DX26+DW26+DR26 -> #VALUE! | EA26: 1 | EB26: =+EOMONTH(EC26,0) -> 45838 | EC26: 45838 | EE26: =+EE25-EF26 -> 1109707.9 | EF26: 0 | EG26: 16421.12 | EH26: =+SUM(EF26:EG26) -> 16421.12 | EI26: 1 | EJ26: =+EC26 -> 45838 | EL26: =+ED26 -> 0 | EM26: =+EG26 -> 16421.12 | EN26: =+EM26+EL26+EG26 -> 32842.24 | EY26: 1 | EZ26: =+EOMONTH(FA26,0) -> 45747 | FA26: 45721 | FC26: =+FC25+FB26-FD26 -> 2794681.5 | FD26: 0 | FE26: 17114.156 | FF26: 86.4 | FG26: =+SUM(FD26:FF26) -> 17200.556 | FI26: 1 | FJ26: =+EOMONTH(FK26,0) -> 45838 | FK26: 45832 | FM26: =+FM25-FN26 -> 309433.84 | FN26: 36909.17 | FO26: 4285.87 | FP26: =+SUM(FN26:FO26) -> 41195.04 | FR26: 1 | FS26: =+EOMONTH(FT26,0) -> 45838 | FT26: 45832 | FV26: =+FV25-FW26 -> 309433.84 | FW26: 36909.17 | FX26: 4285.87 | FY26: =+SUM(FW26:FX26) -> 41195.04 | GA26: 1 | GB26: =+EOMONTH(GC26,0) -> 45838 | GC26: 45832 | GE26: =+GE25-GF26 -> 309433.84 | GF26: 36909.17 | GG26: 4285.87 | GH26: =+SUM(GF26:GG26) -> 41195.04 | GJ26: 1 | GK26: =+EOMONTH(GL26,0) -> 45838 | GL26: 45832 | GN26: =+GN25-GO26 -> 309433.84 | GO26: 36909.17 | GP26: 4285.87 | GQ26: =+SUM(GO26:GP26) -> 41195.04 | GS26: 1 | GT26: =+EOMONTH(GU26,0) -> 45838 | GU26: 45814 | GW26: =+GW25-GX26 -> 388403.55 | GX26: 38005.99 | GY26: 5069.14 | GZ26: =+SUM(GX26:GY26) -> 43075.13 | HB26: 1 | HC26: =+EOMONTH(HD26,0) -> 45838 | HD26: 45814 | HF26: 388403.55 | HG26: 38005.99 | HH26: 5069.14 | HI26: 43075.13
